Workbook

Sheet Summary
A1: Treatments & Countermeasures
A4: Summary
A5: Countermeasures | C5: Treatments | E5: Usable
A6: =COUNTA(Countermeasures!B4:B33) -> 30 | C6: =COUNTA(Treatments!B3:B135) -> 133 | E6: =COUNTIF(Treatments!AD3:AD135,"Yes") -> 128
A8: Excluded | C8: 4-5 star treatments | E8: Avg crash reduction (CRF)
A9: =COUNTIF(Treatments!AD3:AD135,"No*") -> 5 | C9: =COUNTIF(Treatments!N3:N135,">=4") -> 112 | E9: =TEXT(AVERAGE(Treatments!Q3:Q135)/100,"0.0%") -> 41.6%
A11: CMF fit with criteria
A12: OK | B12: =COUNTIF(Treatments!AH3:AH135,"OK") -> 39 | C12: Same crashes
A13: Understates | B13: =COUNTIF(Treatments!AH3:AH135,"Understates") -> 57 | C13: CMF is for all crash types
A14: Overstates | B14: =COUNTIF(Treatments!AH3:AH135,"Overstates") -> 25 | C14: CMF is for a narrower group
A15: Check | B15: =COUNTIF(Treatments!AH3:AH135,"Check") -> 7 | C15: Needs a decision
A17: Severity-limited CMFs
A18: Treatments where K-O is not all the same | B18: =SUMPRODUCT(--((Treatments!C3:C135<>Treatments!G3:G135)+(Treatments!D3:D135<>Treatments!G3:G135)+(Treatments!E3:E135<>Treatments!G3:G135)+(Treatments!F3:F135<>Treatments!G3:G135)>0)) -> 45

Sheet Treatment Selector
A1: TREATMENT SELECTOR
B3: INPUTS
B4: Area Type | C4: Any
B5: Location | C5: Any
B6: Traffic Control | C6: Any
B7: Primary Crash Type | C7: Lane Departure
B8: AADT (optional)
B9: Through Lanes (optional)
B10: Speed Limit (optional)
B11: Roadway Type (optional) | C11: Any
B12: Severity focus (optional) | C12: Any
B14: RECOMMENDED TREATMENTS
B15: Rank | C15: Treatment | D15: Countermeasure | E15: Exp. reduction (CRF) | F15: CMF | G15: Star | H15: What it covers | I15: Read this before you use it | J15: Fit score | K15: Source
B16: =IF(AND(M16>0,N16>0),1,"") -> 1 | C16: =IF(AND(M16>0,N16>0),INDEX($B$35:$B$167,N16),"") -> Install Median Barrier | D16: =IF(AND(M16>0,N16>0),INDEX($C$35:$C$167,N16),"") -> CM: Median Barriers | E16: =IF(AND(M16>0,N16>0),TEXT(INDEX($D$35:$D$167,N16)/100,"0.0%"),"") -> 97.0% | F16: =IF(AND(M16>0,N16>0),INDEX($E$35:$E$167,N16),"") -> 0.03 | G16: =IF(AND(M16>0,N16>0),IF(INDEX($F$35:$F$167,N16)<=0,"NR",INDEX($F$35:$F$167,N16)),"") -> 3 | H16: =IF(AND(M16>0,N16>0),INDEX($Z$35:$Z$167,N16),"") -> All crashes / Only: Cross median | I16: =IF(AND(M16>0,N16>0),INDEX($AA$35:$AA$167,N16),"") -> OVERSTATES: Cross-median crashes only; criteria also has median rollovers and fixed objects. Study roads: Principal Arterial Other Freeways and Expressways. Not for collectors or locals (team). No AADT range in the study. | J16: =IF(AND(M16>0,N16>0),INDEX($R$35:$R$167,N16),"") -> 97 | K16: =IF(AND(M16>0,N16>0),INDEX($T$35:$T$167,N16),"") -> Original | M16: =LARGE($S$35:$S$167,1) -> 9798.447 | N16: =IFERROR(MATCH(M16,$S$35:$S$167,0),0) -> 53
B17: =IF(AND(M17>0,N17>0),2,"") -> 2 | C17: =IF(AND(M17>0,N17>0),INDEX($B$35:$B$167,N17),"") -> Install A Combination Of Chevron Signs, Curve Warning Signs, And/Or Sequential Flashing Beacons | D17: =IF(AND(M17>0,N17>0),INDEX($C$35:$C$167,N17),"") -> CM: Enhanced Delineation for Horizontal Curves | E17: =IF(AND(M17>0,N17>0),TEXT(INDEX($D$35:$D$167,N17)/100,"0.0%"),"") -> 79.0% | F17: =IF(AND(M17>0,N17>0),INDEX($E$35:$E$167,N17),"") -> 0.21 | G17: =IF(AND(M17>0,N17>0),IF(INDEX($F$35:$F$167,N17)<=0,"NR",INDEX($F$35:$F$167,N17)),"") -> 4 | H17: =IF(AND(M17>0,N17>0),INDEX($Z$35:$Z$167,N17),"") -> All crashes / Only: Nighttime | I17: =IF(AND(M17>0,N17>0),INDEX($AA$35:$AA$167,N17),"") -> OVERSTATES: Night crashes only. Study roads: Principal Arterial Other Freeways and Expressways. Not for collectors or locals (team). Study AADT is below the SC average for this class (~17,000). AADT tested: 7,400-13,975. | J17: =IF(AND(M17>0,N17>0),INDEX($R$35:$R$167,N17),"") -> 97 | K17: =IF(AND(M17>0,N17>0),INDEX($T$35:$T$167,N17),"") -> Added | M17: =LARGE($S$35:$S$167,2) -> 9780.958 | N17: =IFERROR(MATCH(M17,$S$35:$S$167,0),0) -> 42
B18: =IF(AND(M18>0,N18>0),3,"") -> 3 | C18: =IF(AND(M18>0,N18>0),INDEX($B$35:$B$167,N18),"") -> Improve Pavement Friction (Chip Seal) | D18: =IF(AND(M18>0,N18>0),INDEX($C$35:$C$167,N18),"") -> CM: Pavement Friction Management | E18: =IF(AND(M18>0,N18>0),TEXT(INDEX($D$35:$D$167,N18)/100,"0.0%"),"") -> 77.8% | F18: =IF(AND(M18>0,N18>0),INDEX($E$35:$E$167,N18),"") -> 0.222 | G18: =IF(AND(M18>0,N18>0),IF(INDEX($F$35:$F$167,N18)<=0,"NR",INDEX($F$35:$F$167,N18)),"") -> 4 | H18: =IF(AND(M18>0,N18>0),INDEX($Z$35:$Z$167,N18),"") -> All crashes / Only: Run off road,Wet road | I18: =IF(AND(M18>0,N18>0),INDEX($AA$35:$AA$167,N18),"") -> AADT tested: 1,280-22,600. | J18: =IF(AND(M18>0,N18>0),INDEX($R$35:$R$167,N18),"") -> 97 | K18: =IF(AND(M18>0,N18>0),INDEX($T$35:$T$167,N18),"") -> Added | M18: =LARGE($S$35:$S$167,3) -> 9779.672 | N18: =IFERROR(MATCH(M18,$S$35:$S$167,0),0) -> 128
B19: =IF(AND(M19>0,N19>0),4,"") -> 4 | C19: =IF(AND(M19>0,N19>0),INDEX($B$35:$B$167,N19),"") -> Install Chevron Signs, Curve Warning Signs, And Sequential Flashing Beacons | D19: =IF(AND(M19>0,N19>0),INDEX($C$35:$C$167,N19),"") -> CM: Enhanced Delineation for Horizontal Curves | E19: =IF(AND(M19>0,N19>0),TEXT(INDEX($D$35:$D$167,N19)/100,"0.0%"),"") -> 76.9% | F19: =IF(AND(M19>0,N19>0),INDEX($E$35:$E$167,N19),"") -> 0.231 | G19: =IF(AND(M19>0,N19>0),IF(INDEX($F$35:$F$167,N19)<=0,"NR",INDEX($F$35:$F$167,N19)),"") -> 4 | H19: =IF(AND(M19>0,N19>0),INDEX($Z$35:$Z$167,N19),"") -> All crashes / Only: Nighttime | I19: =IF(AND(M19>0,N19>0),INDEX($AA$35:$AA$167,N19),"") -> OVERSTATES: Night crashes only. Study roads: Principal Arterial Other Freeways and Expressways. Not for collectors or locals (team). Study AADT is below the SC average for this class (~17,000). AADT tested: 7,400-13,975. | J19: =IF(AND(M19>0,N19>0),INDEX($R$35:$R$167,N19),"") -> 97 | K19: =IF(AND(M19>0,N19>0),INDEX($T$35:$T$167,N19),"") -> Added | M19: =LARGE($S$35:$S$167,4) -> 9778.857 | N19: =IFERROR(MATCH(M19,$S$35:$S$167,0),0) -> 43
B20: =IF(AND(M20>0,N20>0),5,"") -> 5 | C20: =IF(AND(M20>0,N20>0),INDEX($B$35:$B$167,N20),"") -> Improve Pavement Friction (OGFC-Open Graded Friction Course) | D20: =IF(AND(M20>0,N20>0),INDEX($C$35:$C$167,N20),"") -> CM: Pavement Friction Management | E20: =IF(AND(M20>0,N20>0),TEXT(INDEX($D$35:$D$167,N20)/100,"0.0%"),"") -> 69.4% | F20: =IF(AND(M20>0,N20>0),INDEX($E$35:$E$167,N20),"") -> 0.306 | G20: =IF(AND(M20>0,N20>0),IF(INDEX($F$35:$F$167,N20)<=0,"NR",INDEX($F$35:$F$167,N20)),"") -> 4 | H20: =IF(AND(M20>0,N20>0),INDEX($Z$35:$Z$167,N20),"") -> All crashes / Only: Run off road,Wet road | I20: =IF(AND(M20>0,N20>0),INDEX($AA$35:$AA$167,N20),"") -> AADT tested: 14,961-158,656. | J20: =IF(AND(M20>0,N20>0),INDEX($R$35:$R$167,N20),"") -> 97 | K20: =IF(AND(M20>0,N20>0),INDEX($T$35:$T$167,N20),"") -> Added | M20: =LARGE($S$35:$S$167,5) -> 9771.271 | N20: =IFERROR(MATCH(M20,$S$35:$S$167,0),0) -> 129
B21: =IF(AND(M21>0,N21>0),6,"") -> 6 | C21: =IF(AND(M21>0,N21>0),INDEX($B$35:$B$167,N21),"") -> Improve Pavement Friction (UTBWC-Ultra Thin Bonded Wearing Course) | D21: =IF(AND(M21>0,N21>0),INDEX($C$35:$C$167,N21),"") -> CM: Pavement Friction Management | E21: =IF(AND(M21>0,N21>0),TEXT(INDEX($D$35:$D$167,N21)/100,"0.0%"),"") -> 67.0% | F21: =IF(AND(M21>0,N21>0),INDEX($E$35:$E$167,N21),"") -> 0.33 | G21: =IF(AND(M21>0,N21>0),IF(INDEX($F$35:$F$167,N21)<=0,"NR",INDEX($F$35:$F$167,N21)),"") -> 4 | H21: =IF(AND(M21>0,N21>0),INDEX($Z$35:$Z$167,N21),"") -> All crashes / Only: Wet road | I21: =IF(AND(M21>0,N21>0),INDEX($AA$35:$AA$167,N21),"") -> AADT tested: 2,508-50,811. | J21: =IF(AND(M21>0,N21>0),INDEX($R$35:$R$167,N21),"") -> 97 | K21: =IF(AND(M21>0,N21>0),INDEX($T$35:$T$167,N21),"") -> Added | M21: =LARGE($S$35:$S$167,6) -> 9768.87 | N21: =IFERROR(MATCH(M21,$S$35:$S$167,0),0) -> 130
B22: =IF(AND(M22>0,N22>0),7,"") -> 7 | C22: =IF(AND(M22>0,N22>0),INDEX($B$35:$B$167,N22),"") -> Install High Friction Surface Treatment (Hfst) | D22: =IF(AND(M22>0,N22>0),INDEX($C$35:$C$167,N22),"") -> CM: Pavement Friction Management | E22: =IF(AND(M22>0,N22>0),TEXT(INDEX($D$35:$D$167,N22)/100,"0.0%"),"") -> 63.5% | F22: =IF(AND(M22>0,N22>0),INDEX($E$35:$E$167,N22),"") -> 0.365 | G22: =IF(AND(M22>0,N22>0),IF(INDEX($F$35:$F$167,N22)<=0,"NR",INDEX($F$35:$F$167,N22)),"") -> 4 | H22: =IF(AND(M22>0,N22>0),INDEX($Z$35:$Z$167,N22),"") -> Fatal & injury only / All crash types | I22: =IF(AND(M22>0,N22>0),INDEX($AA$35:$AA$167,N22),"") -> No AADT range in the study. | J22: =IF(AND(M22>0,N22>0),INDEX($R$35:$R$167,N22),"") -> 97 | K22: =IF(AND(M22>0,N22>0),INDEX($T$35:$T$167,N22),"") -> Original | M22: =LARGE($S$35:$S$167,7) -> 9765.374 | N22: =IFERROR(MATCH(M22,$S$35:$S$167,0),0) -> 126
B23: =IF(AND(M23>0,N23>0),8,"") -> 8 | C23: =IF(AND(M23>0,N23>0),INDEX($B$35:$B$167,N23),"") -> Install Sinusoidal Rumble Strip | D23: =IF(AND(M23>0,N23>0),INDEX($C$35:$C$167,N23),"") -> CM: Centerline Rumble Strips (Two-Lane Roads) | E23: =IF(AND(M23>0,N23>0),TEXT(INDEX($D$35:$D$167,N23)/100,"0.0%"),"") -> 57.0% | F23: =IF(AND(M23>0,N23>0),INDEX($E$35:$E$167,N23),"") -> 0.43 | G23: =IF(AND(M23>0,N23>0),IF(INDEX($F$35:$F$167,N23)<=0,"NR",INDEX($F$35:$F$167,N23)),"") -> 5 | H23: =IF(AND(M23>0,N23>0),INDEX($Z$35:$Z$167,N23),"") -> All crashes / Only: Other | I23: =IF(AND(M23>0,N23>0),INDEX($AA$35:$AA$167,N23),"") -> No AADT range in the study. | J23: =IF(AND(M23>0,N23>0),INDEX($R$35:$R$167,N23),"") -> 97 | K23: =IF(AND(M23>0,N23>0),INDEX($T$35:$T$167,N23),"") -> Added | M23: =LARGE($S$35:$S$167,8) -> 9759.453 | N23: =IFERROR(MATCH(M23,$S$35:$S$167,0),0) -> 47
B24: =IF(AND(M24>0,N24>0),9,"") -> 9 | C24: =IF(AND(M24>0,N24>0),INDEX($B$35:$B$167,N24),"") -> Improve Pavement Friction (Microsurfacing) | D24: =IF(AND(M24>0,N24>0),INDEX($C$35:$C$167,N24),"") -> CM: Pavement Friction Management | E24: =IF(AND(M24>0,N24>0),TEXT(INDEX($D$35:$D$167,N24)/100,"0.0%"),"") -> 56.0% | F24: =IF(AND(M24>0,N24>0),INDEX($E$35:$E$167,N24),"") -> 0.44 | G24: =IF(AND(M24>0,N24>0),IF(INDEX($F$35:$F$167,N24)<=0,"NR",INDEX($F$35:$F$167,N24)),"") -> 4 | H24: =IF(AND(M24>0,N24>0),INDEX($Z$35:$Z$167,N24),"") -> All crashes / Only: Run off road | I24: =IF(AND(M24>0,N24>0),INDEX($AA$35:$AA$167,N24),"") -> AADT tested: 628-30,314. | J24: =IF(AND(M24>0,N24>0),INDEX($R$35:$R$167,N24),"") -> 97 | K24: =IF(AND(M24>0,N24>0),INDEX($T$35:$T$167,N24),"") -> Added | M24: =LARGE($S$35:$S$167,9) -> 9757.869 | N24: =IFERROR(MATCH(M24,$S$35:$S$167,0),0) -> 131
B25: =IF(AND(M25>0,N25>0),10,"") -> 10 | C25: =IF(AND(M25>0,N25>0),INDEX($B$35:$B$167,N25),"") -> Install Cable Median Barrier (High Tension) | D25: =IF(AND(M25>0,N25>0),INDEX($C$35:$C$167,N25),"") -> CM: Median Barriers | E25: =IF(AND(M25>0,N25>0),TEXT(INDEX($D$35:$D$167,N25)/100,"0.0%"),"") -> 53.0% | F25: =IF(AND(M25>0,N25>0),INDEX($E$35:$E$167,N25),"") -> 0.47 | G25: =IF(AND(M25>0,N25>0),IF(INDEX($F$35:$F$167,N25)<=0,"NR",INDEX($F$35:$F$167,N25)),"") -> 4 | H25: =IF(AND(M25>0,N25>0),INDEX($Z$35:$Z$167,N25),"") -> Fatal & injury only / Only: Other | I25: =IF(AND(M25>0,N25>0),INDEX($AA$35:$AA$167,N25),"") -> CHECK: Study's 'target crashes' not defined in the Clearinghouse entry. Study roads: Principal Arterial Other Freeways and Expressways. Not for collectors or locals (team). AADT tested: 1,508-99,850. | J25: =IF(AND(M25>0,N25>0),INDEX($R$35:$R$167,N25),"") -> 97 | K25: =IF(AND(M25>0,N25>0),INDEX($T$35:$T$167,N25),"") -> Added | M25: =LARGE($S$35:$S$167,10) -> 9754.946 | N25: =IFERROR(MATCH(M25,$S$35:$S$167,0),0) -> 54
B26: =IF(AND(M26>0,N26>0),11,"") -> 11 | C26: =IF(AND(M26>0,N26>0),INDEX($B$35:$B$167,N26),"") -> Improve Pavement Friction (Diamond Grinding) | D26: =IF(AND(M26>0,N26>0),INDEX($C$35:$C$167,N26),"") -> CM: Pavement Friction Management | E26: =IF(AND(M26>0,N26>0),TEXT(INDEX($D$35:$D$167,N26)/100,"0.0%"),"") -> 52.0% | F26: =IF(AND(M26>0,N26>0),INDEX($E$35:$E$167,N26),"") -> 0.48 | G26: =IF(AND(M26>0,N26>0),IF(INDEX($F$35:$F$167,N26)<=0,"NR",INDEX($F$35:$F$167,N26)),"") -> 4 | H26: =IF(AND(M26>0,N26>0),INDEX($Z$35:$Z$167,N26),"") -> All crashes / Only: Wet road | I26: =IF(AND(M26>0,N26>0),INDEX($AA$35:$AA$167,N26),"") -> AADT tested: 10,240-278,200. | J26: =IF(AND(M26>0,N26>0),INDEX($R$35:$R$167,N26),"") -> 97 | K26: =IF(AND(M26>0,N26>0),INDEX($T$35:$T$167,N26),"") -> Added | M26: =LARGE($S$35:$S$167,11) -> 9753.868 | N26: =IFERROR(MATCH(M26,$S$35:$S$167,0),0) -> 132
B27: =IF(AND(M27>0,N27>0),12,"") -> 12 | C27: =IF(AND(M27>0,N27>0),INDEX($B$35:$B$167,N27),"") -> Install Centerline Rumble Strips | D27: =IF(AND(M27>0,N27>0),INDEX($C$35:$C$167,N27),"") -> CM: Centerline Rumble Strips (Two-Lane Roads) | E27: =IF(AND(M27>0,N27>0),TEXT(INDEX($D$35:$D$167,N27)/100,"0.0%"),"") -> 49.0% | F27: =IF(AND(M27>0,N27>0),INDEX($E$35:$E$167,N27),"") -> 0.51 | G27: =IF(AND(M27>0,N27>0),IF(INDEX($F$35:$F$167,N27)<=0,"NR",INDEX($F$35:$F$167,N27)),"") -> 5 | H27: =IF(AND(M27>0,N27>0),INDEX($Z$35:$Z$167,N27),"") -> All crashes / Only: Head on,Sideswipe | I27: =IF(AND(M27>0,N27>0),INDEX($AA$35:$AA$167,N27),"") -> AADT tested: 1,336-13,240. | J27: =IF(AND(M27>0,N27>0),INDEX($R$35:$R$167,N27),"") -> 97 | K27: =IF(AND(M27>0,N27>0),INDEX($T$35:$T$167,N27),"") -> Added | M27: =LARGE($S$35:$S$167,12) -> 9751.452 | N27: =IFERROR(MATCH(M27,$S$35:$S$167,0),0) -> 48
B28: =IF(AND(M28>0,N28>0),13,"") -> 13 | C28: =IF(AND(M28>0,N28>0),INDEX($B$35:$B$167,N28),"") -> Install Centerline Rumble Strips On Tangent Sections | D28: =IF(AND(M28>0,N28>0),INDEX($C$35:$C$167,N28),"") -> CM: Centerline Rumble Strips (Two-Lane Roads) | E28: =IF(AND(M28>0,N28>0),TEXT(INDEX($D$35:$D$167,N28)/100,"0.0%"),"") -> 49.0% | F28: =IF(AND(M28>0,N28>0),INDEX($E$35:$E$167,N28),"") -> 0.51 | G28: =IF(AND(M28>0,N28>0),IF(INDEX($F$35:$F$167,N28)<=0,"NR",INDEX($F$35:$F$167,N28)),"") -> 5 | H28: =IF(AND(M28>0,N28>0),INDEX($Z$35:$Z$167,N28),"") -> All crashes / Only: Head on,Sideswipe | I28: =IF(AND(M28>0,N28>0),INDEX($AA$35:$AA$167,N28),"") -> AADT tested: 1,336-13,240. | J28: =IF(AND(M28>0,N28>0),INDEX($R$35:$R$167,N28),"") -> 97 | K28: =IF(AND(M28>0,N28>0),INDEX($T$35:$T$167,N28),"") -> Added | M28: =LARGE($S$35:$S$167,13) -> 9751.451 | N28: =IFERROR(MATCH(M28,$S$35:$S$167,0),0) -> 49
B29: =IF(AND(M29>0,N29>0),14,"") -> 14 | C29: =IF(AND(M29>0,N29>0),INDEX($B$35:$B$167,N29),"") -> Install Centerline Rumble Strips On Horizontal Curves | D29: =IF(AND(M29>0,N29>0),INDEX($C$35:$C$167,N29),"") -> CM: Centerline Rumble Strips (Two-Lane Roads) | E29: =IF(AND(M29>0,N29>0),TEXT(INDEX($D$35:$D$167,N29)/100,"0.0%"),"") -> 47.0% | F29: =IF(AND(M29>0,N29>0),INDEX($E$35:$E$167,N29),"") -> 0.53 | G29: =IF(AND(M29>0,N29>0),IF(INDEX($F$35:$F$167,N29)<=0,"NR",INDEX($F$35:$F$167,N29)),"") -> 5 | H29: =IF(AND(M29>0,N29>0),INDEX($Z$35:$Z$167,N29),"") -> All crashes / Only: Head on,Sideswipe | I29: =IF(AND(M29>0,N29>0),INDEX($AA$35:$AA$167,N29),"") -> AADT tested: 574-20,784. | J29: =IF(AND(M29>0,N29>0),INDEX($R$35:$R$167,N29),"") -> 97 | K29: =IF(AND(M29>0,N29>0),INDEX($T$35:$T$167,N29),"") -> Added | M29: =LARGE($S$35:$S$167,14) -> 9749.45 | N29: =IFERROR(MATCH(M29,$S$35:$S$167,0),0) -> 50
B30: =IF(AND(M30>0,N30>0),15,"") -> 15 | C30: =IF(AND(M30>0,N30>0),INDEX($B$35:$B$167,N30),"") -> Install W-Beam Guardrail | D30: =IF(AND(M30>0,N30>0),INDEX($C$35:$C$167,N30),"") -> CM: Roadside Barriers (Guardrail) | E30: =IF(AND(M30>0,N30>0),TEXT(INDEX($D$35:$D$167,N30)/100,"0.0%"),"") -> 47.0% | F30: =IF(AND(M30>0,N30>0),INDEX($E$35:$E$167,N30),"") -> 0.53 | G30: =IF(AND(M30>0,N30>0),IF(INDEX($F$35:$F$167,N30)<=0,"NR",INDEX($F$35:$F$167,N30)),"") -> 4 | H30: =IF(AND(M30>0,N30>0),INDEX($Z$35:$Z$167,N30),"") -> Fatal & injury only / Only: Nighttime,Run off road | I30: =IF(AND(M30>0,N30>0),INDEX($AA$35:$AA$167,N30),"") -> OVERSTATES: Night run-off-road only. Study roads: Principal Arterial Other Freeways and Expressways. Not for collectors or locals (team). AADT tested: 35,000-104,600. | J30: =IF(AND(M30>0,N30>0),INDEX($R$35:$R$167,N30),"") -> 97 | K30: =IF(AND(M30>0,N30>0),INDEX($T$35:$T$167,N30),"") -> Added | M30: =LARGE($S$35:$S$167,15) -> 9748.942 | N30: =IFERROR(MATCH(M30,$S$35:$S$167,0),0) -> 58
B33: v engine (hidden) v
A34: idx | B34: Treatment | C34: CM | D34: CRF | E34: CMF | F34: Star | G34: AADTmin | H34: AADTmax | I34: Area | J34: Loc | K34: Control | L34: Tags | M34: crashSc | N34: areaSc | O34: locSc | P34: ctrlSc | Q34: aadtSc | R34: Fit | S34: Priority | T34: Source | U34: RoadCls | V34: roadSc | W34: Use | X34: SevScope | Y34: sevSc | Z34: Scope text | AA34: Caution
A35: 1 | B35: =Treatments!A3 -> Install Automated Section Speed Enforcement System | C35: =Treatments!B3 -> CM: Appropriate Speed Limits for All Road Users | D35: =Treatments!Q3 -> 36.8 | E35: =Treatments!P3 -> 0.632 | F35: =IF(ISNUMBER(Treatments!N3),Treatments!N3,0) -> 5 | G35: =IF(ISNUMBER(Treatments!U3),Treatments!U3,"") | H35: =IF(ISNUMBER(Treatments!V3),Treatments!V3,"") | I35: Urban | J35: Roadway Segment | K35: Any | L35: |All|Speeding| | M35: =IF(ISNUMBER(SEARCH("|"&$C$7&"|",L35)),45,IF(ISNUMBER(SEARCH("|All|",L35)),18,0)) -> 18 | N35: =IF(OR($C$4="Any",I35="All"),12,IF(ISNUMBER(SEARCH($C$4,I35)),12,0)) -> 12 | O35: =IF(OR($C$5="Any",J35="Any",J35=$C$5),13,0) -> 13 | P35: =IF(OR($C$6="Any",K35="Any",K35=$C$6),10,0) -> 10 | Q35: =IF($C$8="",4,IF(AND(ISNUMBER(G35),ISNUMBER(H35)),IF(AND($C$8>=G35,$C$8<=H35),7,0),4)) -> 4 | R35: =M35+N35+O35+P35+Q35+V35+Y35 -> 70 | S35: =IF(OR(M35=0,W35=0),-A35,R35*100+D35+F35*0.5-A35*0.001) -> 7039.299 | T35: =Treatments!M3 -> Original | U35: Freeway/Expressway | V35: =IF(OR($C$11="Any",U35="Any",U35=$C$11),8,0) -> 8 | W35: =IF(LEFT(Treatments!AD3,3)="Yes",1,0) -> 1 | X35: =Treatments!AE3 -> Fatal & injury only | Y35: =IF($C$12="Any",5,IF($C$12=X35,5,IF(AND($C$12="Fatal & injury only",X35="All crashes"),3,0))) -> 5 | Z35: =Treatments!AE3&" / "&Treatments!AF3 -> Fatal & injury only / All crash types | AA35: =IF(OR(Treatments!AH3="Overstates",Treatments!AH3="Check"),UPPER(Treatments!AH3)&": "&Treatments!AI3&". ","")&IF(Treatments!AG3="","",Treatments!AG3) -> Study roads: Principal Arterial Other Freeways and Expressways. Not for collectors or locals (team). No AADT range in the study.
A36: 2 | B36: =Treatments!A4 -> Implement Automated Speed Enforcement Cameras | C36: =Treatments!B4 -> CM: Appropriate Speed Limits for All Road Users | D36: =Treatments!Q4 -> 54 | E36: =Treatments!P4 -> 0.46 | F36: =IF(ISNUMBER(Treatments!N4),Treatments!N4,0) -> 4 | G36: =IF(ISNUMBER(Treatments!U4),Treatments!U4,"") | H36: =IF(ISNUMBER(Treatments!V4),Treatments!V4,"") | I36: Urban | J36: Roadway Segment | K36: Any | L36: |All|Speeding| | M36: =IF(ISNUMBER(SEARCH("|"&$C$7&"|",L36)),45,IF(ISNUMBER(SEARCH("|All|",L36)),18,0)) -> 18 | N36: =IF(OR($C$4="Any",I36="All"),12,IF(ISNUMBER(SEARCH($C$4,I36)),12,0)) -> 12 | O36: =IF(OR($C$5="Any",J36="Any",J36=$C$5),13,0) -> 13 | P36: =IF(OR($C$6="Any",K36="Any",K36=$C$6),10,0) -> 10 | Q36: =IF($C$8="",4,IF(AND(ISNUMBER(G36),ISNUMBER(H36)),IF(AND($C$8>=G36,$C$8<=H36),7,0),4)) -> 4 | R36: =M36+N36+O36+P36+Q36+V36+Y36 -> 70 | S36: =IF(OR(M36=0,W36=0),-A36,R36*100+D36+F36*0.5-A36*0.001) -> 7055.998 | T36: =Treatments!M4 -> Original | U36: Arterial/Collector | V36: =IF(OR($C$11="Any",U36="Any",U36=$C$11),8,0) -> 8 | W36: =IF(LEFT(Treatments!AD4,3)="Yes",1,0) -> 1 | X36: =Treatments!AE4 -> All crashes | Y36: =IF($C$12="Any",5,IF($C$12=X36,5,IF(AND($C$12="Fatal & injury only",X36="All crashes"),3,0))) -> 5 | Z36: =Treatments!AE4&" / "&Treatments!AF4 -> All crashes / All crash types | AA36: =IF(OR(Treatments!AH4="Overstates",Treatments!AH4="Check"),UPPER(Treatments!AH4)&": "&Treatments!AI4&". ","")&IF(Treatments!AG4="","",Treatments!AG4) -> No AADT range in the study.
A37: 3 | B37: =Treatments!A5 -> Install Variable Speed Limit (Vsl) | C37: =Treatments!B5 -> CM: Appropriate Speed Limits for All Road Users | D37: =Treatments!Q5 -> 34 | E37: =Treatments!P5 -> 0.66 | F37: =IF(ISNUMBER(Treatments!N5),Treatments!N5,0) -> 3 | G37: =IF(ISNUMBER(Treatments!U5),Treatments!U5,"") -> 10194 | H37: =IF(ISNUMBER(Treatments!V5),Treatments!V5,"") -> 11090 | I37: All | J37: Roadway Segment | K37: Any | L37: |All|Speeding| | M37: =IF(ISNUMBER(SEARCH("|"&$C$7&"|",L37)),45,IF(ISNUMBER(SEARCH("|All|",L37)),18,0)) -> 18 | N37: =IF(OR($C$4="Any",I37="All"),12,IF(ISNUMBER(SEARCH($C$4,I37)),12,0)) -> 12 | O37: =IF(OR($C$5="Any",J37="Any",J37=$C$5),13,0) -> 13 | P37: =IF(OR($C$6="Any",K37="Any",K37=$C$6),10,0) -> 10 | Q37: =IF($C$8="",4,IF(AND(ISNUMBER(G37),ISNUMBER(H37)),IF(AND($C$8>=G37,$C$8<=H37),7,0),4)) -> 4 | R37: =M37+N37+O37+P37+Q37+V37+Y37 -> 70 | S37: =IF(OR(M37=0,W37=0),-A37,R37*100+D37+F37*0.5-A37*0.001) -> 7035.497 | T37: =Treatments!M5 -> Original | U37: Freeway/Expressway | V37: =IF(OR($C$11="Any",U37="Any",U37=$C$11),8,0) -> 8 | W37: =IF(LEFT(Treatments!AD5,3)="Yes",1,0) -> 1 | X37: =Treatments!AE5 -> All crashes | Y37: =IF($C$12="Any",5,IF($C$12=X37,5,IF(AND($C$12="Fatal & injury only",X37="All crashes"),3,0))) -> 5 | Z37: =Treatments!AE5&" / "&Treatments!AF5 -> All crashes / All crash types | AA37: =IF(OR(Treatments!AH5="Overstates",Treatments!AH5="Check"),UPPER(Treatments!AH5)&": "&Treatments!AI5&". ","")&IF(Treatments!AG5="","",Treatments!AG5) -> Study roads: Principal Arterial Interstate. Not for collectors or locals (team). Study AADT is below the SC average for this class (~17,000). AADT tested: 10,194-11,090.
A38: 4 | B38: =Treatments!A6 -> Install Variable Speed Limit | C38: =Treatments!B6 -> CM: Appropriate Speed Limits for All Road Users | D38: =Treatments!Q6 -> 13.9 | E38: =Treatments!P6 -> 0.861 | F38: =IF(ISNUMBER(Treatments!N6),Treatments!N6,0) -> 4 | G38: =IF(ISNUMBER(Treatments!U6),Treatments!U6,"") -> 53729 | H38: =IF(ISNUMBER(Treatments!V6),Treatments!V6,"") -> 282619 | I38: All | J38: Roadway Segment | K38: Any | L38: |All|Speeding| | M38: =IF(ISNUMBER(SEARCH("|"&$C$7&"|",L38)),45,IF(ISNUMBER(SEARCH("|All|",L38)),18,0)) -> 18 | N38: =IF(OR($C$4="Any",I38="All"),12,IF(ISNUMBER(SEARCH($C$4,I38)),12,0)) -> 12 | O38: =IF(OR($C$5="Any",J38="Any",J38=$C$5),13,0) -> 13 | P38: =IF(OR($C$6="Any",K38="Any",K38=$C$6),10,0) -> 10 | Q38: =IF($C$8="",4,IF(AND(ISNUMBER(G38),ISNUMBER(H38)),IF(AND($C$8>=G38,$C$8<=H38),7,0),4)) -> 4 | R38: =M38+N38+O38+P38+Q38+V38+Y38 -> 70 | S38: =IF(OR(M38=0,W38=0),-A38,R38*100+D38+F38*0.5-A38*0.001) -> 7015.896 | T38: =Treatments!M6 -> Added | U38: Freeway/Expressway | V38: =IF(OR($C$11="Any",U38="Any",U38=$C$11),8,0) -> 8 | W38: =IF(LEFT(Treatments!AD6,3)="Yes",1,0) -> 1 | X38: =Treatments!AE6 -> Fatal & injury only | Y38: =IF($C$12="Any",5,IF($C$12=X38,5,IF(AND($C$12="Fatal & injury only",X38="All crashes"),3,0))) -> 5 | Z38: =Treatments!AE6&" / "&Treatments!AF6 -> Fatal & injury only / All crash types | AA38: =IF(OR(Treatments!AH6="Overstates",Treatments!AH6="Check"),UPPER(Treatments!AH6)&": "&Treatments!AI6&". ","")&IF(Treatments!AG6="","",Treatments!AG6) -> Study roads: Principal Arterial Interstate. Not for collectors or locals (team). AADT tested: 53,729-282,619.
A39: 5 | B39: =Treatments!A7 -> Install Dynamic Speed Feedback Sign | C39: =Treatments!B7 -> CM: Appropriate Speed Limits for All Road Users | D39: =Treatments!Q7 -> 7 | E39: =Treatments!P7 -> 0.93 | F39: =IF(ISNUMBER(Treatments!N7),Treatments!N7,0) -> 4 | G39: =IF(ISNUMBER(Treatments!U7),Treatments!U7,"") -> 400 | H39: =IF(ISNUMBER(Treatments!V7),Treatments!V7,"") -> 8400 | I39: Rural | J39: Roadway Segment | K39: Any | L39: |All|Speeding| | M39: =IF(ISNUMBER(SEARCH("|"&$C$7&"|",L39)),45,IF(ISNUMBER(SEARCH("|All|",L39)),18,0)) -> 18 | N39: =IF(OR($C$4="Any",I39="All"),12,IF(ISNUMBER(SEARCH($C$4,I39)),12,0)) -> 12 | O39: =IF(OR($C$5="Any",J39="Any",J39=$C$5),13,0) -> 13 | P39: =IF(OR($C$6="Any",K39="Any",K39=$C$6),10,0) -> 10 | Q39: =IF($C$8="",4,IF(AND(ISNUMBER(G39),ISNUMBER(H39)),IF(AND($C$8>=G39,$C$8<=H39),7,0),4)) -> 4 | R39: =M39+N39+O39+P39+Q39+V39+Y39 -> 70 | S39: =IF(OR(M39=0,W39=0),-A39,R39*100+D39+F39*0.5-A39*0.001) -> 7008.995 | T39: =Treatments!M7 -> Added | U39: Any | V39: =IF(OR($C$11="Any",U39="Any",U39=$C$11),8,0) -> 8 | W39: =IF(LEFT(Treatments!AD7,3)="Yes",1,0) -> 1 | X39: =Treatments!AE7 -> All crashes | Y39: =IF($C$12="Any",5,IF($C$12=X39,5,IF(AND($C$12="Fatal & injury only",X39="All crashes"),3,0))) -> 5 | Z39: =Treatments!AE7&" / "&Treatments!AF7 -> All crashes / All crash types | AA39: =IF(OR(Treatments!AH7="Overstates",Treatments!AH7="Check"),UPPER(Treatments!AH7)&": "&Treatments!AI7&". ","")&IF(Treatments!AG7="","",Treatments!AG7) -> AADT tested: 400-8,400.
A40: 6 | B40: =Treatments!A8 -> Install Automated Section Speed Enforcement System | C40: =Treatments!B8 -> CM: Appropriate Speed Limits for All Road Users | D40: =Treatments!Q8 -> 43.7 | E40: =Treatments!P8 -> 0.563 | F40: =IF(ISNUMBER(Treatments!N8),Treatments!N8,0) -> 5 | G40: =IF(ISNUMBER(Treatments!U8),Treatments!U8,"") | H40: =IF(ISNUMBER(Treatments!V8),Treatments!V8,"") | I40: Urban | J40: Roadway Segment | K40: Any | L40: |Speeding| | M40: =IF(ISNUMBER(SEARCH("|"&$C$7&"|",L40)),45,IF(ISNUMBER(SEARCH("|All|",L40)),18,0)) -> 0 | N40: =IF(OR($C$4="Any",I40="All"),12,IF(ISNUMBER(SEARCH($C$4,I40)),12,0)) -> 12 | O40: =IF(OR($C$5="Any",J40="Any",J40=$C$5),13,0) -> 13 | P40: =IF(OR($C$6="Any",K40="Any",K40=$C$6),10,0) -> 10 | Q40: =IF($C$8="",4,IF(AND(ISNUMBER(G40),ISNUMBER(H40)),IF(AND($C$8>=G40,$C$8<=H40),7,0),4)) -> 4 | R40: =M40+N40+O40+P40+Q40+V40+Y40 -> 52 | S40: =IF(OR(M40=0,W40=0),-A40,R40*100+D40+F40*0.5-A40*0.001) -> -6 | T40: =Treatments!M8 -> Added | U40: Freeway/Expressway | V40: =IF(OR($C$11="Any",U40="Any",U40=$C$11),8,0) -> 8 | W40: =IF(LEFT(Treatments!AD8,3)="Yes",1,0) -> 1 | X40: =Treatments!AE8 -> All crashes | Y40: =IF($C$12="Any",5,IF($C$12=X40,5,IF(AND($C$12="Fatal & injury only",X40="All crashes"),3,0))) -> 5 | Z40: =Treatments!AE8&" / "&Treatments!AF8 -> All crashes / Only: Single vehicle | AA40: =IF(OR(Treatments!AH8="Overstates",Treatments!AH8="Check"),UPPER(Treatments!AH8)&": "&Treatments!AI8&". ","")&IF(Treatments!AG8="","",Treatments!AG8) -> OVERSTATES: Single-vehicle crashes only. Study roads: Principal Arterial Other Freeways and Expressways. Not for collectors or locals (team). No AADT range in the study.
A41: 7 | B41: =Treatments!A9 -> Implement Mobile Automated Speed Enforcement System | C41: =Treatments!B9 -> CM: Appropriate Speed Limits for All Road Users | D41: =Treatments!Q9 -> 20.1 | E41: =Treatments!P9 -> 0.799 | F41: =IF(ISNUMBER(Treatments!N9),Treatments!N9,0) -> 5 | G41: =IF(ISNUMBER(Treatments!U9),Treatments!U9,"") -> 2079 | H41: =IF(ISNUMBER(Treatments!V9),Treatments!V9,"") -> 22960 | I41: Urban | J41: Roadway Segment | K41: Any | L41: |All|Speeding| | M41: =IF(ISNUMBER(SEARCH("|"&$C$7&"|",L41)),45,IF(ISNUMBER(SEARCH("|All|",L41)),18,0)) -> 18 | N41: =IF(OR($C$4="Any",I41="All"),12,IF(ISNUMBER(SEARCH($C$4,I41)),12,0)) -> 12 | O41: =IF(OR($C$5="Any",J41="Any",J41=$C$5),13,0) -> 13 | P41: =IF(OR($C$6="Any",K41="Any",K41=$C$6),10,0) -> 10 | Q41: =IF($C$8="",4,IF(AND(ISNUMBER(G41),ISNUMBER(H41)),IF(AND($C$8>=G41,$C$8<=H41),7,0),4)) -> 4 | R41: =M41+N41+O41+P41+Q41+V41+Y41 -> 70 | S41: =IF(OR(M41=0,W41=0),-A41,R41*100+D41+F41*0.5-A41*0.001) -> 7022.593 | T41: =Treatments!M9 -> Added | U41: Arterial/Collector | V41: =IF(OR($C$11="Any",U41="Any",U41=$C$11),8,0) -> 8 | W41: =IF(LEFT(Treatments!AD9,3)="Yes",1,0) -> 1 | X41: =Treatments!AE9 -> Fatal & injury only | Y41: =IF($C$12="Any",5,IF($C$12=X41,5,IF(AND($C$12="Fatal & injury only",X41="All crashes"),3,0))) -> 5 | Z41: =Treatments!AE9&" / "&Treatments!AF9 -> Fatal & injury only / All crash types | AA41: =IF(OR(Treatments!AH9="Overstates",Treatments!AH9="Check"),UPPER(Treatments!AH9)&": "&Treatments!AI9&". ","")&IF(Treatments!AG9="","",Treatments!AG9) -> AADT tested: 2,079-22,960.
A42: 8 | B42: =Treatments!A10 -> Implement Automated Speed Enforcement Cameras | C42: =Treatments!B10 -> CM: Appropriate Speed Limits for All Road Users | D42: =Treatments!Q10 -> 67 | E42: =Treatments!P10 -> 0.33 | F42: =IF(ISNUMBER(Treatments!N10),Treatments!N10,0) -> 4 | G42: =IF(ISNUMBER(Treatments!U10),Treatments!U10,"") | H42: =IF(ISNUMBER(Treatments!V10),Treatments!V10,"") | I42: Urban | J42: Roadway Segment | K42: Any | L42: |Speeding| | M42: =IF(ISNUMBER(SEARCH("|"&$C$7&"|",L42)),45,IF(ISNUMBER(SEARCH("|All|",L42)),18,0)) -> 0 | N42: =IF(OR($C$4="Any",I42="All"),12,IF(ISNUMBER(SEARCH($C$4,I42)),12,0)) -> 12 | O42: =IF(OR($C$5="Any",J42="Any",J42=$C$5),13,0) -> 13 | P42: =IF(OR($C$6="Any",K42="Any",K42=$C$6),10,0) -> 10 | Q42: =IF($C$8="",4,IF(AND(ISNUMBER(G42),ISNUMBER(H42)),IF(AND($C$8>=G42,$C$8<=H42),7,0),4)) -> 4 | R42: =M42+N42+O42+P42+Q42+V42+Y42 -> 52 | S42: =IF(OR(M42=0,W42=0),-A42,R42*100+D42+F42*0.5-A42*0.001) -> -8 | T42: =Treatments!M10 -> Added | U42: Arterial/Collector | V42: =IF(OR($C$11="Any",U42="Any",U42=$C$11),8,0) -> 8 | W42: =IF(LEFT(Treatments!AD10,3)="Yes",1,0) -> 1 | X42: =Treatments!AE10 -> PDO only | Y42: =IF($C$12="Any",5,IF($C$12=X42,5,IF(AND($C$12="Fatal & injury only",X42="All crashes"),3,0))) -> 5 | Z42: =Treatments!AE10&" / "&Treatments!AF10 -> PDO only / Only: Single vehicle | AA42: =IF(OR(Treatments!AH10="Overstates",Treatments!AH10="Check"),UPPER(Treatments!AH10)&": "&Treatments!AI10&". ","")&IF(Treatments!AG10="","",Treatments!AG10) -> OVERSTATES: Single-vehicle, PDO, off-peak only. No AADT range in the study.
A43: 9 | B43: =Treatments!A11 -> Install Automated Section Speed Enforcement System On Curves | C43: =Treatments!B11 -> CM: Appropriate Speed Limits for All Road Users | D43: =Treatments!Q11 -> 43 | E43: =Treatments!P11 -> 0.57 | F43: =IF(ISNUMBER(Treatments!N11),Treatments!N11,0) -> 4 | G43: =IF(ISNUMBER(Treatments!U11),Treatments!U11,"") -> 23000 | H43: =IF(ISNUMBER(Treatments!V11),Treatments!V11,"") -> 42000 | I43: All | J43: Roadway Segment | K43: Any | L43: |All|Speeding| | M43: =IF(ISNUMBER(SEARCH("|"&$C$7&"|",L43)),45,IF(ISNUMBER(SEARCH("|All|",L43)),18,0)) -> 18 | N43: =IF(OR($C$4="Any",I43="All"),12,IF(ISNUMBER(SEARCH($C$4,I43)),12,0)) -> 12 | O43: =IF(OR($C$5="Any",J43="Any",J43=$C$5),13,0) -> 13 | P43: =IF(OR($C$6="Any",K43="Any",K43=$C$6),10,0) -> 10 | Q43: =IF($C$8="",4,IF(AND(ISNUMBER(G43),ISNUMBER(H43)),IF(AND($C$8>=G43,$C$8<=H43),7,0),4)) -> 4 | R43: =M43+N43+O43+P43+Q43+V43+Y43 -> 70 | S43: =IF(OR(M43=0,W43=0),-A43,R43*100+D43+F43*0.5-A43*0.001) -> 7044.991 | T43: =Treatments!M11 -> Added | U43: Freeway/Expressway | V43: =IF(OR($C$11="Any",U43="Any",U43=$C$11),8,0) -> 8 | W43: =IF(LEFT(Treatments!AD11,3)="Yes",1,0) -> 1 | X43: =Treatments!AE11 -> All crashes | Y43: =IF($C$12="Any",5,IF($C$12=X43,5,IF(AND($C$12="Fatal & injury only",X43="All crashes"),3,0))) -> 5 | Z43: =Treatments!AE11&" / "&Treatments!AF11 -> All crashes / All crash types | AA43: =IF(OR(Treatments!AH11="Overstates",Treatments!AH11="Check"),UPPER(Treatments!AH11)&": "&Treatments!AI11&". ","")&IF(Treatments!AG11="","",Treatments!AG11) -> Study roads: Principal Arterial Other Freeways and Expressways. Not for collectors or locals (team). AADT tested: 23,000-42,000.
A44: 10 | B44: =Treatments!A12 -> Convert Traditional Or Flush Buffered Bike Lane To Sbl With Flexi-Posts | C44: =Treatments!B12 -> CM: Bicycle Lanes | D44: =Treatments!Q12 -> 53.2 | E44: =Treatments!P12 -> 0.468 | F44: =IF(ISNUMBER(Treatments!N12),Treatments!N12,0) -> 4 | G44: =IF(ISNUMBER(Treatments!U12),Treatments!U12,"") | H44: =IF(ISNUMBER(Treatments!V12),Treatments!V12,"") | I44: Urban | J44: Roadway Segment | K44: Any | L44: |Bicycle| | M44: =IF(ISNUMBER(SEARCH("|"&$C$7&"|",L44)),45,IF(ISNUMBER(SEARCH("|All|",L44)),18,0)) -> 0 | N44: =IF(OR($C$4="Any",I44="All"),12,IF(ISNUMBER(SEARCH($C$4,I44)),12,0)) -> 12 | O44: =IF(OR($C$5="Any",J44="Any",J44=$C$5),13,0) -> 13 | P44: =IF(OR($C$6="Any",K44="Any",K44=$C$6),10,0) -> 10 | Q44: =IF($C$8="",4,IF(AND(ISNUMBER(G44),ISNUMBER(H44)),IF(AND($C$8>=G44,$C$8<=H44),7,0),4)) -> 4 | R44: =M44+N44+O44+P44+Q44+V44+Y44 -> 52 | S44: =IF(OR(M44=0,W44=0),-A44,R44*100+D44+F44*0.5-A44*0.001) -> -10 | T44: =Treatments!M12 -> Original | U44: Any | V44: =IF(OR($C$11="Any",U44="Any",U44=$C$11),8,0) -> 8 | W44: =IF(LEFT(Treatments!AD12,3)="Yes",1,0) -> 1 | X44: =Treatments!AE12 -> All crashes | Y44: =IF($C$12="Any",5,IF($C$12=X44,5,IF(AND($C$12="Fatal & injury only",X44="All crashes"),3,0))) -> 5 | Z44: =Treatments!AE12&" / "&Treatments!AF12 -> All crashes / Only: Vehicle/bicycle | AA44: =IF(OR(Treatments!AH12="Overstates",Treatments!AH12="Check"),UPPER(Treatments!AH12)&": "&Treatments!AI12&". ","")&IF(Treatments!AG12="","",Treatments!AG12) -> No AADT range in the study.
...

Sheet Countermeasures
A1: COUNTERMEASURES
A2: Criteria use the field names and dropdown labels from the SMS Condition Builder. Each line is one row in the builder; keep the parentheses as groups. Codes and the rules behind them are on the Field Reference sheet.
A3: Emphasis area | B3: Countermeasure | C3: Area type | D3: Location | E3: Crash types | F3: Traffic control | G3: Site conditions | H3: Crash criteria (as entered in the SMS / AASHTOWare Condition Builder) | I3: Notes | J3: Open item | K3: # Treat.
A4: Speed Management | B4: CM: Appropriate Speed Limits for All Road Users | C4: Any | D4: Any | E4: Speeding-related | F4: Any | G4: - | H4: Probable Cause = Exceeded Speed Limit | I4: Too Fast for Conditions left out on purpose (team decision, Jan 2025). Most CMFs in this group are for all crashes on the corridor, so the benefit comes out low. | J4: Ask Numetric what 'Speeding Related' contains. If it leaves out Too Fast for Conditions, use Speeding Related = Yes instead. | K4: =COUNTIF(Treatments!B:B,B4) -> 9
A5: Pedestrian/Bicyclist | B5: CM: Bicycle Lanes | C5: Urban | D5: Any | E5: Bicycle | F5: Any | G5: - | H5: ( Unit Type = Pedalcycle OR First Harmful Event = Pedalcycle ) | I5: Vulnerable Road User Related also pulls in pedestrians, so it is not used here. Pedalcycle is code 26 in the SMS (25 on the new TR-310). | K5: =COUNTIF(Treatments!B:B,B5) -> 8
A6: Pedestrian/Bicyclist | B6: CM: Crosswalk Visibility Enhancements | C6: Urban / Suburban | D6: Intersection | E6: Pedestrian | F6: Any | G6: - | H6: Pedestrian Related = Yes AND Intersection Related = Yes | I6: Bicyclists dropped: all three CMFs are vehicle-pedestrian. CMF 436 is night-only (see Treatments). | K6: =COUNTIF(Treatments!B:B,B6) -> 3
A7: Pedestrian/Bicyclist | B7: CM: Leading Pedestrian Interval | C7: Urban / Suburban | D7: Intersection | E7: Pedestrian | F7: Signal | G7: - | H7: Pedestrian Related = Yes AND Intersection Related = Yes AND Traffic Control = Traffic Signal | I7: Turning-vehicle filter removed. Both LPI CMFs are for all vehicle-pedestrian crashes at the intersection, not only turning ones. | J7: Confirm the dropdown label for signals under Traffic Control. | K7: =COUNTIF(Treatments!B:B,B7) -> 2
A8: Pedestrian/Bicyclist | B8: CM: Medians and Pedestrian Refuge Islands in Urban and Suburban Areas | C8: Urban / Suburban | D8: Midblock | E8: Pedestrian | F8: Any | G8: 4+ through lanes | H8: Pedestrian Related = Yes AND Intersection Related = No AND Area Type = Urban AND Through Lanes >= 4 | I8: Lanes come from the Roadway data. CMF 2219 (0.29) is for all crashes, not pedestrian crashes. | K8: =COUNTIF(Treatments!B:B,B8) -> 3
A9: Pedestrian/Bicyclist | B9: CM: Pedestrian Hybrid Beacons | C9: Urban / Suburban | D9: Midblock | E9: Pedestrian | F9: No signal | G9: Speed limit 35+ or 4+ lanes | H9: Pedestrian Related = Yes AND Intersection Related = No AND Traffic Control ≠ Traffic Signal AND ( Speed Limit >= 35 OR Through Lanes >= 4 ) | I9: PHB and RRFB had identical criteria. Split by speed and lanes following the FHWA STEP guide for uncontrolled crossings. 35-40 mph overlaps on purpose; both are options there. | J9: Confirm Speed Limit is available under Roadway. | K9: =COUNTIF(Treatments!B:B,B9) -> 3
A10: Pedestrian/Bicyclist | B10: CM: Rectangular Rapid Flashing Beacons (RRFB) | C10: Urban / Suburban | D10: Midblock | E10: Pedestrian | F10: No signal | G10: Speed limit 40 or less | H10: Pedestrian Related = Yes AND Intersection Related = No AND Traffic Control ≠ Traffic Signal AND Speed Limit <= 40 | I10: RRFBs are not recommended on high-speed roads (FHWA STEP). Bicyclists dropped: both CMFs are vehicle-pedestrian. | J10: Same Speed Limit check as PHB. | K10: =COUNTIF(Treatments!B:B,B10) -> 2
A11: Pedestrian/Bicyclist | B11: CM: Road Diets (Roadway Reconfiguration) | C11: Urban | D11: Segment | E11: Rear-end, Head-on, Angle, Ped, Bike | F11: Any | G11: 4 lanes, undivided, AADT 20,000 or less | H11: Area Type = Urban AND Trafficway = Two-Way, Not Divided AND Through Lanes = 4 AND AADT <= 20000 AND ( Manner of Collision = Rear End OR Manner of Collision = Head On OR Manner of Collision = Angle OR Pedestrian Related = Yes OR Unit Type = Pedalcycle ) | I11: AADT limit from the FHWA Road Diet guide. Freeway exclusion dropped: Two-Way, Not Divided already removes them. All three CMFs are for all crashes, so the benefit comes out low. | J11: Angle may show as three entries in the dropdown (SMS codes 41, 42, 43). Select all three. | K11: =COUNTIF(Treatments!B:B,B11) -> 3
A12: Pedestrian/Bicyclist | B12: CM: Walkways | C12: Any | D12: Midblock | E12: Pedestrian | F12: Any | G12: - | H12: Pedestrian Related = Yes AND Intersection Related = No | I12: Walking-along-the-road filter dropped: the sidewalk CMF (11246) covers all vehicle-pedestrian crashes. | J12: If the SMS has a pedestrian action field, add 'walking along roadway' back. | K12: =COUNTIF(Treatments!B:B,B12) -> 1
A13: Roadway Departure | B13: CM: Enhanced Delineation for Horizontal Curves | C13: Any | D13: Segment (curve) | E13: Lane departure | F13: Any | G13: Curve | H13: Lane Departure = Yes AND Junction Type = NON-JUNCTION AND ( Road Character = Curve-Level OR Road Character = Curve-On Grade OR Road Character = Curve-Hillcrest ) AND Probable Cause ≠ Obstruction in Roadway AND Probable Cause ≠ Debris | I13: Changed from Roadway Departure to Lane Departure so head-ons on the curve count; most curve CMFs cover all crashes at the curve. Curve Left / Curve Right do not exist in the SMS - Road Character does. | J13: Team: OK with Lane Departure here? 5 of the 9 CMFs are night-only (see Treatments). | K13: =COUNTIF(Treatments!B:B,B13) -> 9
A14: Roadway Departure | B14: CM: Centerline Rumble Strips (Two-Lane Roads) | C14: Rural | D14: Segment | E14: Head-on, Sideswipe opp. direction | F14: Any | G14: 2 lanes, undivided | H14: Lane Departure = Yes AND Roadway Departure = No AND Junction Type = NON-JUNCTION AND Trafficway = Two-Way, Not Divided AND Through Lanes = 2 AND Area Type = Rural | I14: Lane Departure minus Roadway Departure leaves Head On + Sideswipe, Opposite Direction, which is what the CMFs measured. Rural added per the meeting; every CMF here is rural. | K14: =COUNTIF(Treatments!B:B,B14) -> 5
A15: Roadway Departure | B15: CM: Shoulder Rumble Strips | C15: Rural | D15: Segment | E15: Run-off-road | F15: Any | G15: - | H15: Roadway Departure = Yes AND Junction Type = NON-JUNCTION AND Area Type = Rural AND Probable Cause ≠ Obstruction in Roadway AND Probable Cause ≠ Debris | I15: Same crash group as SafetyEdge and Wider Edge Lines. That is fine: they are alternative fixes for the same crashes and AASHTOWare ranks them by B/C. | K15: =COUNTIF(Treatments!B:B,B15) -> 4
A16: Roadway Departure | B16: CM: Median Barriers | C16: Any | D16: Segment | E16: Cross-median, Head-on, Sideswipe opp., median ROR / fixed object | F16: Any | G16: Divided, no barrier, AADT over 20,000 | H16: Junction Type = NON-JUNCTION AND Trafficway = Two-Way, Divided, Unprotected Median AND AADT > 20000 AND ( Manner of Collision = Head On OR Manner of Collision = Sideswipe, Opposite Direction OR Sequence of Events = Cross Median/Center OR Sequence of Events = Ran off Road Left OR First Harmful Event Location = Median ) AND First Harmful Event Location ≠ Roadside AND First Harmful Event Location ≠ Outside Trafficway AND Crash Harmful Event ≠ Median Barrier | I16: Trafficway drops undivided roads (centerline crashes), one-way ramps and roads that already have a barrier (I-20 crash 23239996). First Harmful Event Location = Median brings in every object in the median - piers, abutments, walls, poles, ditches - in one line. 'First Harmful Event ≠ Ran off Road Right' replaced with Location ≠ Roadside so a driver who goes right, overcorrects and crosses the median stays in. AADT > 20,000 matches AASHTO RDG Fig. 6-1. | J16: Median width (30 ft or less per RDG) is not in the crash data - check against inventory. Wrong-way head-ons can't be removed with crash-level fields. CMF 7040 (0.03) is cross-median only. | K16: =COUNTIF(Treatments!B:B,B16) -> 2
A17: Roadway Departure | B17: CM: Roadside Design Improvements at Curves | C17: Any | D17: Segment (curve) | E17: Run-off-road, fixed object, rollover | F17: Any | G17: Curve | H17: Roadway Departure = Yes AND Junction Type = NON-JUNCTION AND ( Road Character = Curve-Level OR Road Character = Curve-On Grade OR Road Character = Curve-Hillcrest ) AND ( First Harmful Event Location = Roadside OR First Harmful Event Location = Shoulder ) AND Probable Cause ≠ Obstruction in Roadway AND Probable Cause ≠ Debris | I17: Object list replaced by First Harmful Event Location. The old codes were wrong in the SMS: Tree is 60, Utility Pole is 61, and 59 is Other (Wall, Bldg, Tunnel). Median crashes go to Median Barriers so nothing is counted twice. | J17: CMF 7179 is for median slopes on freeways, not curves. | K17: =COUNTIF(Treatments!B:B,B17) -> 3
A18: Roadway Departure | B18: CM: Roadside Barriers (Guardrail) | C18: Any | D18: Segment | E18: Run-off-road, fixed object | F18: Any | G18: - | H18: Roadway Departure = Yes AND Junction Type = NON-JUNCTION AND ( First Harmful Event Location = Roadside OR First Harmful Event Location = Shoulder ) AND Crash Harmful Event ≠ Guardrail Face AND Crash Harmful Event ≠ Guardrail End AND Crash Harmful Event ≠ Median Barrier AND Probable Cause ≠ Obstruction in Roadway AND Probable Cause ≠ Debris | I18: Existing-barrier hits excluded by name. Old codes 41/42/44 were wrong in the SMS (41 = Bridge Parapet End, 42 = Bridge Pier, 44 = Culvert). 'Number of Vehicles = 1' dropped - Roadway Departure is already single-vehicle. | J18: Both CMFs are night-only, KA / KAB. | K18: =COUNTIF(Treatments!B:B,B18) -> 2
A19: Roadway Departure | B19: CM: SafetyEdge℠ | C19: Rural | D19: Segment | E19: Run-off-road | F19: Any | G19: - | H19: Roadway Departure = Yes AND Junction Type = NON-JUNCTION AND Area Type = Rural AND Probable Cause ≠ Obstruction in Roadway AND Probable Cause ≠ Debris | I19: Same group as Shoulder Rumble Strips on purpose (see row 14). | K19: =COUNTIF(Treatments!B:B,B19) -> 2
A20: Roadway Departure | B20: CM: Wider Edge Lines | C20: Rural | D20: Segment | E20: Run-off-road | F20: Any | G20: - | H20: Roadway Departure = Yes AND Junction Type = NON-JUNCTION AND Area Type = Rural AND Probable Cause ≠ Obstruction in Roadway AND Probable Cause ≠ Debris | I20: Four of the five CMFs are for all crashes, so the benefit comes out low. CMF 4739 is daytime only. | K20: =COUNTIF(Treatments!B:B,B20) -> 5
A21: Intersections | B21: CM: Backplates with Retroreflective Borders | C21: Any | D21: Intersection | E21: Angle, Rear-end | F21: Signal | G21: - | H21: Intersection Related = Yes AND Traffic Control = Traffic Signal AND ( Manner of Collision = Angle OR Manner of Collision = Rear End ) | K21: =COUNTIF(Treatments!B:B,B21) -> 1
A22: Intersections | B22: CM: Corridor Access Management | C22: Any | D22: Intersection or driveway | E22: Angle, Rear-end, Head-on | F22: Any | G22: - | H22: ( Intersection Related = Yes OR Junction Type = Driveway ) AND ( Manner of Collision = Angle OR Manner of Collision = Rear End OR Manner of Collision = Head On ) | I22: Intersection Related does not include driveways, so Driveway is added by hand. Pedestrian/bike exclusion dropped: those crashes are Non Collision in Manner of Collision, so the MOC line already removes them. | J22: CMF 10375 is for non-intersection crashes. | K22: =COUNTIF(Treatments!B:B,B22) -> 6
A23: Intersections | B23: CM: Dedicated Right- Lanes at Intersections | C23: Any | D23: Intersection | E23: Rear-end, Angle | F23: Any | G23: - | H23: Intersection Related = Yes AND ( Manner of Collision = Rear End OR Manner of Collision = Angle ) | I23: 'Number of Vehicles >= 2' dropped - Rear End and Angle already mean two vehicles. | J23: Two CMFs (8431, 8499) are right-turn crashes only. | K23: =COUNTIF(Treatments!B:B,B23) -> 6
A24: Intersections | B24: CM: Dedicated Left- Lanes at Intersections | C24: Any | D24: Intersection | E24: Angle, Rear-end, Head-on | F24: Any | G24: - | H24: Intersection Related = Yes AND ( Manner of Collision = Angle OR Manner of Collision = Rear End OR Manner of Collision = Head On ) | K24: =COUNTIF(Treatments!B:B,B24) -> 7
A25: Intersections | B25: CM: Reduced Left-Turn Conflict Intersections | C25: Any | D25: Intersection | E25: Angle, Head-on | F25: Any | G25: - | H25: Intersection Related = Yes AND ( Manner of Collision = Angle OR Manner of Collision = Head On ) | K25: =COUNTIF(Treatments!B:B,B25) -> 6
A26: Intersections | B26: CM: Protected/Permissive Left-Turn Phasing | C26: Any | D26: Intersection | E26: Angle, Head-on, left turn | F26: Signal | G26: - | H26: Intersection Related = Yes AND Traffic Control = Traffic Signal AND ( Manner of Collision = Angle OR Manner of Collision = Head On ) AND Vehicle Maneuver = Turning Left | I26: Turning Left is a unit field; '=' works fine (any unit turning left). | J26: Confirm the name of the unit movement field and the 'Turning Left' label. | K26: =COUNTIF(Treatments!B:B,B26) -> 6
A27: Intersections | B27: CM: Roundabouts | C27: Any | D27: Intersection | E27: Angle, Head-on | F27: Any | G27: - | H27: Intersection Related = Yes AND Junction Type ≠ Traffic Circle AND ( Manner of Collision = Angle OR Manner of Collision = Head On ) | I27: Existing traffic circles removed. Most roundabout CMFs are for all crashes, so the benefit comes out low. | K27: =COUNTIF(Treatments!B:B,B27) -> 8
A28: Intersections | B28: CM: Convert Minor-Road Stop to All-Way Stop Control | C28: Any | D28: Intersection | E28: Angle | F28: Stop | G28: - | H28: Intersection Related = Yes AND Traffic Control = Stop Sign AND Manner of Collision = Angle | J28: Confirm the dropdown label for stop signs. | K28: =COUNTIF(Treatments!B:B,B28) -> 1
A29: Intersections | B29: CM: Intersection Conflict Warning Systems (ICWS) | C29: Rural | D29: Intersection | E29: Angle | F29: Stop | G29: - | H29: Intersection Related = Yes AND Traffic Control = Stop Sign AND Manner of Collision = Angle AND Area Type = Rural | K29: =COUNTIF(Treatments!B:B,B29) -> 6
A30: Intersections | B30: CM: Systemic Application of Multiple Low-Cost Countermeasures at Stop-Controlled Intersections | C30: Any | D30: Intersection | E30: All | F30: Stop | G30: T, Y or four-way | H30: Traffic Control = Stop Sign AND ( Junction Type = T-Intersection OR Junction Type = Y-Intersection OR Junction Type = Four-Way Intersection ) | I30: Signalized intersections are out because of the Stop Sign line. | J30: CMF 8970 is from signalized intersections - doesn't belong in this group. | K30: =COUNTIF(Treatments!B:B,B30) -> 5
A31: Intersections | B31: CM: Yellow Change Intervals | C31: Any | D31: Intersection | E31: Rear-end, Angle (red-light running) | F31: Signal | G31: - | H31: Intersection Related = Yes AND Traffic Control = Traffic Signal AND ( Manner of Collision = Rear End OR Manner of Collision = Angle ) AND Probable Cause = Disregarded Sign/Signal | I31: The SC code list has no 'Ran Red Light'; Disregarded Sign/Signal is the closest. | J31: Both CMFs are for all crashes, so this filter makes the benefit very low. Team decision. | K31: =COUNTIF(Treatments!B:B,B31) -> 2
A32: Crosscutting | B32: CM: Lighting | C32: Any | D32: Any | E32: Night, all except rear-end | F32: Any | G32: - | H32: ( Light Condition = Dark (No Lights) OR Light Condition = Dark (Street Lamps Not Lit) OR Light Condition = Dark (Lighting Unspecified) OR Light Condition = Dark (Street Lamp Lit) ) AND Manner of Collision ≠ Rear End | I32: SMS light codes are 4-7, not the new-form 04-06 (in the SMS 5 = Street Lamp Lit and 6 = Lamps Not Lit). Take out 'Street Lamp Lit' to look only at roads with no lighting. | J32: CMF 7784 is rear-end only, but rear-ends are excluded. Drop one or the other. | K32: =COUNTIF(Treatments!B:B,B32) -> 5
A33: Crosscutting | B33: CM: Pavement Friction Management | C33: Any | D33: Any | E33: Wet road: run-off-road or curve | F33: Any | G33: Wet pavement | H33: Road Surface Condition = Wet AND ( Roadway Departure = Yes OR Road Character = Curve-Level OR Road Character = Curve-On Grade OR Road Character = Curve-Hillcrest ) AND Probable Cause ≠ Obstruction in Roadway AND Probable Cause ≠ Debris | I33: Ice and slush dropped: none of the 8 CMFs measured ice. Fixed a parenthesis that never closed in the old version. | K33: =COUNTIF(Treatments!B:B,B33) -> 8

Sheet Treatments
A1: TREATMENTS
A2: Treatment | B2: Countermeasure | C2: Default CMF (K) | D2: Default CMF (A) | E2: Default CMF (B) | F2: Default CMF (C) | G2: Default CMF (O) | H2: Default Service Years | I2: Date Added | J2: Added By | K2: Checked By | L2: CMF ID | M2: Source | N2: Star | O2: Area Type | P2: CMF (study) | Q2: CRF % | R2: KABCO Severity | S2: Crash Type (CMF) | T2: Roadway Type | U2: AADT Min | V2: AADT Max | W2: AADT Avg | X2: Intersection / Control | Y2: Speed Limit | Z2: In HSM | AA2: Sample (sites / crashes) | AB2: Study Method | AC2: Background / Notes | AD2: Use? | AE2: Severity scope | AF2: Crash-type scope | AG2: Notes for SC use | AH2: Fit with CM criteria | AI2: Why
A3: Install Automated Section Speed Enforcement System | B3: CM: Appropriate Speed Limits for All Road Users | C3: =IF(OR($R3="All",$R3="Not specified",ISNUMBER(SEARCH("K (",$R3))),$P3,1) -> 0.632 | D3: =IF(OR($R3="All",$R3="Not specified",ISNUMBER(SEARCH("A (",$R3))),$P3,1) -> 0.632 | E3: =IF(OR($R3="All",$R3="Not specified",ISNUMBER(SEARCH("B (",$R3))),$P3,1) -> 0.632 | F3: =IF(OR($R3="All",$R3="Not specified",ISNUMBER(SEARCH("C (",$R3))),$P3,1) -> 0.632 | G3: =IF(OR($R3="All",$R3="Not specified",ISNUMBER(SEARCH("O (",$R3))),$P3,1) -> 1 | H3: 20 | L3: CMF: 7718 | M3: Original | N3: 5 | O3: Urban | P3: 0.632 | Q3: =IF(ISNUMBER(P3),ROUND((1-P3)*100,1),"NR") -> 36.8 | R3: K (fatal),A (serious injury),B (minor injury),C (possible injury) | S3: All | T3: Principal Arterial Other Freeways and Expressways | U3: NR | V3: NR | W3: =IF(AND(ISNUMBER(U3),ISNUMBER(V3)),ROUND((U3+V3)/2,0),IF(ISNUMBER(U3),U3,IF(ISNUMBER(V3),V3,"NR"))) -> NR | X3: Not reported | Y3: 80-80 | Z3: no | AA3: 50+ sites / 700+ crashes | AB3: Before/after using empirical Bayes or full Bayes | AC3: The authors note that crash reduction effects decreased over time and speed, speed variability, and non-compliance to speed limits significantly increased over time. | AD3: Yes | AE3: Fatal & injury only | AF3: All crash types | AG3: Study roads: Principal Arterial Other Freeways and Expressways. Not for collectors or locals (team). No AADT range in the study. | AH3: Understates | AI3: CMF is for all crash types
A4: Implement Automated Speed Enforcement Cameras | B4: CM: Appropriate Speed Limits for All Road Users | C4: =IF(OR($R4="All",$R4="Not specified",ISNUMBER(SEARCH("K (",$R4))),$P4,1) -> 0.46 | D4: =IF(OR($R4="All",$R4="Not specified",ISNUMBER(SEARCH("A (",$R4))),$P4,1) -> 0.46 | E4: =IF(OR($R4="All",$R4="Not specified",ISNUMBER(SEARCH("B (",$R4))),$P4,1) -> 0.46 | F4: =IF(OR($R4="All",$R4="Not specified",ISNUMBER(SEARCH("C (",$R4))),$P4,1) -> 0.46 | G4: =IF(OR($R4="All",$R4="Not specified",ISNUMBER(SEARCH("O (",$R4))),$P4,1) -> 0.46 | H4: 20 | L4: CMF: 2915 | M4: Original | N4: 4 | O4: Urban | P4: 0.46 | Q4: =IF(ISNUMBER(P4),ROUND((1-P4)*100,1),"NR") -> 54 | R4: All | S4: All | T4: Principal Arterial Other | U4: NR | V4: NR | W4: =IF(AND(ISNUMBER(U4),ISNUMBER(V4)),ROUND((U4+V4)/2,0),IF(ISNUMBER(U4),U4,IF(ISNUMBER(V4),V4,"NR"))) -> NR | X4: Not reported | Y4: NR | Z4: no | AA4: 25-49 sites / unknown crashes | AB4: Before/after using empirical Bayes or full Bayes | AC4: CMF is for "target" crashes. Target crashes are defined as those that occur during non-peak periods. Peak periods (6AM - 9 AM and 4PM - 7PM); Non-peak periods (remaining 18 hrs for weekdays, 24 hrs for weekends and holidays). | AD4: Yes | AE4: All crashes | AF4: All crash types | AG4: No AADT range in the study. | AH4: Understates | AI4: CMF is for all crash types
A5: Install Variable Speed Limit (Vsl) | B5: CM: Appropriate Speed Limits for All Road Users | C5: =IF(OR($R5="All",$R5="Not specified",ISNUMBER(SEARCH("K (",$R5))),$P5,1) -> 0.66 | D5: =IF(OR($R5="All",$R5="Not specified",ISNUMBER(SEARCH("A (",$R5))),$P5,1) -> 0.66 | E5: =IF(OR($R5="All",$R5="Not specified",ISNUMBER(SEARCH("B (",$R5))),$P5,1) -> 0.66 | F5: =IF(OR($R5="All",$R5="Not specified",ISNUMBER(SEARCH("C (",$R5))),$P5,1) -> 0.66 | G5: =IF(OR($R5="All",$R5="Not specified",ISNUMBER(SEARCH("O (",$R5))),$P5,1) -> 0.66 | H5: 20 | L5: CMF: 11002 | M5: Original | N5: 3 | O5: Not specified | P5: 0.66 | Q5: =IF(ISNUMBER(P5),ROUND((1-P5)*100,1),"NR") -> 34 | R5: All | S5: All | T5: Principal Arterial Interstate | U5: 10194 | V5: 11090 | W5: =IF(AND(ISNUMBER(U5),ISNUMBER(V5)),ROUND((U5+V5)/2,0),IF(ISNUMBER(U5),U5,IF(ISNUMBER(V5),V5,"NR"))) -> 10642 | X5: Not reported | Y5: 35-75 | Z5: no | AA5: 50-99 sites / 700+ crashes | AB5: Regression cross-section | AD5: Yes | AE5: All crashes | AF5: All crash types | AG5: Study roads: Principal Arterial Interstate. Not for collectors or locals (team). Study AADT is below the SC average for this class (~17,000). AADT tested: 10,194-11,090. | AH5: Understates | AI5: CMF is for all crash types
A6: Install Variable Speed Limit | B6: CM: Appropriate Speed Limits for All Road Users | C6: =IF(OR($R6="All",$R6="Not specified",ISNUMBER(SEARCH("K (",$R6))),$P6,1) -> 0.861 | D6: =IF(OR($R6="All",$R6="Not specified",ISNUMBER(SEARCH("A (",$R6))),$P6,1) -> 0.861 | E6: =IF(OR($R6="All",$R6="Not specified",ISNUMBER(SEARCH("B (",$R6))),$P6,1) -> 0.861 | F6: =IF(OR($R6="All",$R6="Not specified",ISNUMBER(SEARCH("C (",$R6))),$P6,1) -> 0.861 | G6: =IF(OR($R6="All",$R6="Not specified",ISNUMBER(SEARCH("O (",$R6))),$P6,1) -> 1 | H6: 20 | L6: CMF: 11832 | M6: Added | N6: 4 | O6: Not reported | P6: 0.861 | Q6: =IF(ISNUMBER(P6),ROUND((1-P6)*100,1),"NR") -> 13.9 | R6: K (fatal), A (serious injury), B (minor injury), C (possible injury) | S6: All | T6: Principal Arterial Interstate | U6: 53729 | V6: 282619 | W6: =IF(AND(ISNUMBER(U6),ISNUMBER(V6)),ROUND((U6+V6)/2,0),IF(ISNUMBER(U6),U6,IF(ISNUMBER(V6),V6,"NR"))) -> 168174 | X6: Not reported | Y6: NR | Z6: no | AA6: 50+ sites / unknown crashes | AB6: Before/after using empirical Bayes or full Bayes | AC6: This CMF is for I-5. | AD6: Yes | AE6: Fatal & injury only | AF6: All crash types | AG6: Study roads: Principal Arterial Interstate. Not for collectors or locals (team). AADT tested: 53,729-282,619. | AH6: Understates | AI6: CMF is for all crash types
A7: Install Dynamic Speed Feedback Sign | B7: CM: Appropriate Speed Limits for All Road Users | C7: =IF(OR($R7="All",$R7="Not specified",ISNUMBER(SEARCH("K (",$R7))),$P7,1) -> 0.93 | D7: =IF(OR($R7="All",$R7="Not specified",ISNUMBER(SEARCH("A (",$R7))),$P7,1) -> 0.93 | E7: =IF(OR($R7="All",$R7="Not specified",ISNUMBER(SEARCH("B (",$R7))),$P7,1) -> 0.93 | F7: =IF(OR($R7="All",$R7="Not specified",ISNUMBER(SEARCH("C (",$R7))),$P7,1) -> 0.93 | G7: =IF(OR($R7="All",$R7="Not specified",ISNUMBER(SEARCH("O (",$R7))),$P7,1) -> 0.93 | H7: 20 | L7: CMF: 6886 | M7: Added | N7: 4 | O7: Rural | P7: 0.93 | Q7: =IF(ISNUMBER(P7),ROUND((1-P7)*100,1),"NR") -> 7 | R7: All | S7: All | T7: Not specified | U7: 400 | V7: 8400 | W7: =IF(AND(ISNUMBER(U7),ISNUMBER(V7)),ROUND((U7+V7)/2,0),IF(ISNUMBER(U7),U7,IF(ISNUMBER(V7),V7,"NR"))) -> 4400 | X7: Not reported | Y7: 50-65 | Z7: no | AA7: <25 or unknown sites / <250 crashes | AB7: Before/after using empirical Bayes or full Bayes | AC7: This CMF applies to two-lane rural horizontal curves for crashes involving vehicles traveling in the direction of the DSFS system. | AD7: Yes | AE7: All crashes | AF7: All crash types | AG7: AADT tested: 400-8,400. | AH7: Understates | AI7: CMF is for all crash types
A8: Install Automated Section Speed Enforcement System | B8: CM: Appropriate Speed Limits for All Road Users | C8: =IF(OR($R8="All",$R8="Not specified",ISNUMBER(SEARCH("K (",$R8))),$P8,1) -> 0.563 | D8: =IF(OR($R8="All",$R8="Not specified",ISNUMBER(SEARCH("A (",$R8))),$P8,1) -> 0.563 | E8: =IF(OR($R8="All",$R8="Not specified",ISNUMBER(SEARCH("B (",$R8))),$P8,1) -> 0.563 | F8: =IF(OR($R8="All",$R8="Not specified",ISNUMBER(SEARCH("C (",$R8))),$P8,1) -> 0.563 | G8: =IF(OR($R8="All",$R8="Not specified",ISNUMBER(SEARCH("O (",$R8))),$P8,1) -> 0.563 | H8: 20 | L8: CMF: 7714 | M8: Added | N8: 5 | O8: Urban | P8: 0.563 | Q8: =IF(ISNUMBER(P8),ROUND((1-P8)*100,1),"NR") -> 43.7 | R8: All | S8: Single vehicle | T8: Principal Arterial Other Freeways and Expressways | U8: NR | V8: NR | W8: =IF(AND(ISNUMBER(U8),ISNUMBER(V8)),ROUND((U8+V8)/2,0),IF(ISNUMBER(U8),U8,IF(ISNUMBER(V8),V8,"NR"))) -> NR | X8: Not reported | Y8: 80-80 | Z8: no | AA8: 50+ sites / 700+ crashes | AB8: Before/after using empirical Bayes or full Bayes | AC8: The authors note that crash reduction effects decreased over time and speed, speed variability, and non-compliance to speed limits significantly increased over time. | AD8: Yes | AE8: All crashes | AF8: Only: Single vehicle | AG8: Study roads: Principal Arterial Other Freeways and Expressways. Not for collectors or locals (team). No AADT range in the study. | AH8: Overstates | AI8: Single-vehicle crashes only
A9: Implement Mobile Automated Speed Enforcement System | B9: CM: Appropriate Speed Limits for All Road Users | C9: =IF(OR($R9="All",$R9="Not specified",ISNUMBER(SEARCH("K (",$R9))),$P9,1) -> 0.799 | D9: =IF(OR($R9="All",$R9="Not specified",ISNUMBER(SEARCH("A (",$R9))),$P9,1) -> 0.799 | E9: =IF(OR($R9="All",$R9="Not specified",ISNUMBER(SEARCH("B (",$R9))),$P9,1) -> 0.799 | F9: =IF(OR($R9="All",$R9="Not specified",ISNUMBER(SEARCH("C (",$R9))),$P9,1) -> 0.799 | G9: =IF(OR($R9="All",$R9="Not specified",ISNUMBER(SEARCH("O (",$R9))),$P9,1) -> 1 | H9: 20 | L9: CMF: 7582 | M9: Added | N9: 5 | O9: Urban | P9: 0.799 | Q9: =IF(ISNUMBER(P9),ROUND((1-P9)*100,1),"NR") -> 20.1 | R9: K (fatal),A (serious injury),B (minor injury),C (possible injury) | S9: All | T9: Principal Arterial Other | U9: 2079 | V9: 22960 | W9: =IF(AND(ISNUMBER(U9),ISNUMBER(V9)),ROUND((U9+V9)/2,0),IF(ISNUMBER(U9),U9,IF(ISNUMBER(V9),V9,"NR"))) -> 12520 | X9: Not reported | Y9: NR | Z9: no | AA9: 50+ sites / 700+ crashes | AB9: Before/after using empirical Bayes or full Bayes | AC9: The number of crashes in the after period were not reported in this study | AD9: Yes | AE9: Fatal & injury only | AF9: All crash types | AG9: AADT tested: 2,079-22,960. | AH9: Understates | AI9: CMF is for all crash types
