Workbook

Sheet Summary
A1: Treatments & Countermeasures
A4: Summary
A5: Countermeasures | C5: Treatments | E5: Usable
A6: =COUNTA(Countermeasures!B3:B32) -> 30 | C6: =COUNTA(Treatments!B3:B135) -> 133 | E6: =COUNTIF(Treatments!AD3:AD135,"Yes") -> 128
A8: Excluded | C8: 4-5 star treatments | E8: Avg crash reduction (CRF)
A9: =COUNTIF(Treatments!AD3:AD135,"No*") -> 5 | C9: =COUNTIF(Treatments!N3:N135,">=4") -> 112 | E9: =TEXT(AVERAGE(Treatments!Q3:Q135)/100,"0.0%") -> 41.6%

Sheet Treatment Selector
A1: TREATMENT SELECTOR
B3: INPUTS
B4: Area Type | C4: Any
B5: Location | C5: Any
B6: Traffic Control | C6: Any
B7: Primary Crash Type | C7: Lane Departure
B8: AADT (optional)
B9: Through Lanes (optional)
B10: Speed Limit (optional)
B11: Roadway Type (optional) | C11: Any
B12: Severity focus (optional) | C12: Any
B14: RECOMMENDED TREATMENTS
B15: Rank | C15: Treatment | D15: Countermeasure | E15: Exp. reduction (CRF) | F15: CMF | G15: Star | H15: What it covers | I15: Read this before you use it | J15: Fit score | K15: Source
B16: =IF(AND(M16>0,N16>0),1,"") -> 1 | C16: =IF(AND(M16>0,N16>0),INDEX($B$35:$B$167,N16),"") -> Install Median Barrier | D16: =IF(AND(M16>0,N16>0),INDEX($C$35:$C$167,N16),"") -> CM: Median Barriers | E16: =IF(AND(M16>0,N16>0),TEXT(INDEX($D$35:$D$167,N16)/100,"0.0%"),"") -> 97.0% | F16: =IF(AND(M16>0,N16>0),INDEX($E$35:$E$167,N16),"") -> 0.03 | G16: =IF(AND(M16>0,N16>0),IF(INDEX($F$35:$F$167,N16)<=0,"NR",INDEX($F$35:$F$167,N16)),"") -> 3 | H16: =IF(AND(M16>0,N16>0),INDEX($Z$35:$Z$167,N16),"") -> All crashes / Only: Cross median | I16: =IF(AND(M16>0,N16>0),INDEX($AA$35:$AA$167,N16),"") -> #REF! | J16: =IF(AND(M16>0,N16>0),INDEX($R$35:$R$167,N16),"") -> 97 | K16: =IF(AND(M16>0,N16>0),INDEX($T$35:$T$167,N16),"") -> Original | M16: =LARGE($S$35:$S$167,1) -> 9798.447 | N16: =IFERROR(MATCH(M16,$S$35:$S$167,0),0) -> 53
B17: =IF(AND(M17>0,N17>0),2,"") -> 2 | C17: =IF(AND(M17>0,N17>0),INDEX($B$35:$B$167,N17),"") -> Install A Combination Of Chevron Signs, Curve Warning Signs, And/Or Sequential Flashing Beacons | D17: =IF(AND(M17>0,N17>0),INDEX($C$35:$C$167,N17),"") -> CM: Enhanced Delineation for Horizontal Curves | E17: =IF(AND(M17>0,N17>0),TEXT(INDEX($D$35:$D$167,N17)/100,"0.0%"),"") -> 79.0% | F17: =IF(AND(M17>0,N17>0),INDEX($E$35:$E$167,N17),"") -> 0.21 | G17: =IF(AND(M17>0,N17>0),IF(INDEX($F$35:$F$167,N17)<=0,"NR",INDEX($F$35:$F$167,N17)),"") -> 4 | H17: =IF(AND(M17>0,N17>0),INDEX($Z$35:$Z$167,N17),"") -> All crashes / Only: Nighttime | I17: =IF(AND(M17>0,N17>0),INDEX($AA$35:$AA$167,N17),"") -> #REF! | J17: =IF(AND(M17>0,N17>0),INDEX($R$35:$R$167,N17),"") -> 97 | K17: =IF(AND(M17>0,N17>0),INDEX($T$35:$T$167,N17),"") -> Added | M17: =LARGE($S$35:$S$167,2) -> 9780.958 | N17: =IFERROR(MATCH(M17,$S$35:$S$167,0),0) -> 42
B18: =IF(AND(M18>0,N18>0),3,"") -> 3 | C18: =IF(AND(M18>0,N18>0),INDEX($B$35:$B$167,N18),"") -> Improve Pavement Friction (Chip Seal) | D18: =IF(AND(M18>0,N18>0),INDEX($C$35:$C$167,N18),"") -> CM: Pavement Friction Management | E18: =IF(AND(M18>0,N18>0),TEXT(INDEX($D$35:$D$167,N18)/100,"0.0%"),"") -> 77.8% | F18: =IF(AND(M18>0,N18>0),INDEX($E$35:$E$167,N18),"") -> 0.222 | G18: =IF(AND(M18>0,N18>0),IF(INDEX($F$35:$F$167,N18)<=0,"NR",INDEX($F$35:$F$167,N18)),"") -> 4 | H18: =IF(AND(M18>0,N18>0),INDEX($Z$35:$Z$167,N18),"") -> All crashes / Only: Run off road,Wet road | I18: =IF(AND(M18>0,N18>0),INDEX($AA$35:$AA$167,N18),"") -> #REF! | J18: =IF(AND(M18>0,N18>0),INDEX($R$35:$R$167,N18),"") -> 97 | K18: =IF(AND(M18>0,N18>0),INDEX($T$35:$T$167,N18),"") -> Added | M18: =LARGE($S$35:$S$167,3) -> 9779.672 | N18: =IFERROR(MATCH(M18,$S$35:$S$167,0),0) -> 128
B19: =IF(AND(M19>0,N19>0),4,"") -> 4 | C19: =IF(AND(M19>0,N19>0),INDEX($B$35:$B$167,N19),"") -> Install Chevron Signs, Curve Warning Signs, And Sequential Flashing Beacons | D19: =IF(AND(M19>0,N19>0),INDEX($C$35:$C$167,N19),"") -> CM: Enhanced Delineation for Horizontal Curves | E19: =IF(AND(M19>0,N19>0),TEXT(INDEX($D$35:$D$167,N19)/100,"0.0%"),"") -> 76.9% | F19: =IF(AND(M19>0,N19>0),INDEX($E$35:$E$167,N19),"") -> 0.231 | G19: =IF(AND(M19>0,N19>0),IF(INDEX($F$35:$F$167,N19)<=0,"NR",INDEX($F$35:$F$167,N19)),"") -> 4 | H19: =IF(AND(M19>0,N19>0),INDEX($Z$35:$Z$167,N19),"") -> All crashes / Only: Nighttime | I19: =IF(AND(M19>0,N19>0),INDEX($AA$35:$AA$167,N19),"") -> #REF! | J19: =IF(AND(M19>0,N19>0),INDEX($R$35:$R$167,N19),"") -> 97 | K19: =IF(AND(M19>0,N19>0),INDEX($T$35:$T$167,N19),"") -> Added | M19: =LARGE($S$35:$S$167,4) -> 9778.857 | N19: =IFERROR(MATCH(M19,$S$35:$S$167,0),0) -> 43
B20: =IF(AND(M20>0,N20>0),5,"") -> 5 | C20: =IF(AND(M20>0,N20>0),INDEX($B$35:$B$167,N20),"") -> Improve Pavement Friction (OGFC-Open Graded Friction Course) | D20: =IF(AND(M20>0,N20>0),INDEX($C$35:$C$167,N20),"") -> CM: Pavement Friction Management | E20: =IF(AND(M20>0,N20>0),TEXT(INDEX($D$35:$D$167,N20)/100,"0.0%"),"") -> 69.4% | F20: =IF(AND(M20>0,N20>0),INDEX($E$35:$E$167,N20),"") -> 0.306 | G20: =IF(AND(M20>0,N20>0),IF(INDEX($F$35:$F$167,N20)<=0,"NR",INDEX($F$35:$F$167,N20)),"") -> 4 | H20: =IF(AND(M20>0,N20>0),INDEX($Z$35:$Z$167,N20),"") -> All crashes / Only: Run off road,Wet road | I20: =IF(AND(M20>0,N20>0),INDEX($AA$35:$AA$167,N20),"") -> #REF! | J20: =IF(AND(M20>0,N20>0),INDEX($R$35:$R$167,N20),"") -> 97 | K20: =IF(AND(M20>0,N20>0),INDEX($T$35:$T$167,N20),"") -> Added | M20: =LARGE($S$35:$S$167,5) -> 9771.271 | N20: =IFERROR(MATCH(M20,$S$35:$S$167,0),0) -> 129
B21: =IF(AND(M21>0,N21>0),6,"") -> 6 | C21: =IF(AND(M21>0,N21>0),INDEX($B$35:$B$167,N21),"") -> Improve Pavement Friction (UTBWC-Ultra Thin Bonded Wearing Course) | D21: =IF(AND(M21>0,N21>0),INDEX($C$35:$C$167,N21),"") -> CM: Pavement Friction Management | E21: =IF(AND(M21>0,N21>0),TEXT(INDEX($D$35:$D$167,N21)/100,"0.0%"),"") -> 67.0% | F21: =IF(AND(M21>0,N21>0),INDEX($E$35:$E$167,N21),"") -> 0.33 | G21: =IF(AND(M21>0,N21>0),IF(INDEX($F$35:$F$167,N21)<=0,"NR",INDEX($F$35:$F$167,N21)),"") -> 4 | H21: =IF(AND(M21>0,N21>0),INDEX($Z$35:$Z$167,N21),"") -> All crashes / Only: Wet road | I21: =IF(AND(M21>0,N21>0),INDEX($AA$35:$AA$167,N21),"") -> #REF! | J21: =IF(AND(M21>0,N21>0),INDEX($R$35:$R$167,N21),"") -> 97 | K21: =IF(AND(M21>0,N21>0),INDEX($T$35:$T$167,N21),"") -> Added | M21: =LARGE($S$35:$S$167,6) -> 9768.87 | N21: =IFERROR(MATCH(M21,$S$35:$S$167,0),0) -> 130
B22: =IF(AND(M22>0,N22>0),7,"") -> 7 | C22: =IF(AND(M22>0,N22>0),INDEX($B$35:$B$167,N22),"") -> Install High Friction Surface Treatment (Hfst) | D22: =IF(AND(M22>0,N22>0),INDEX($C$35:$C$167,N22),"") -> CM: Pavement Friction Management | E22: =IF(AND(M22>0,N22>0),TEXT(INDEX($D$35:$D$167,N22)/100,"0.0%"),"") -> 63.5% | F22: =IF(AND(M22>0,N22>0),INDEX($E$35:$E$167,N22),"") -> 0.365 | G22: =IF(AND(M22>0,N22>0),IF(INDEX($F$35:$F$167,N22)<=0,"NR",INDEX($F$35:$F$167,N22)),"") -> 4 | H22: =IF(AND(M22>0,N22>0),INDEX($Z$35:$Z$167,N22),"") -> Fatal & injury only / All crash types | I22: =IF(AND(M22>0,N22>0),INDEX($AA$35:$AA$167,N22),"") -> #REF! | J22: =IF(AND(M22>0,N22>0),INDEX($R$35:$R$167,N22),"") -> 97 | K22: =IF(AND(M22>0,N22>0),INDEX($T$35:$T$167,N22),"") -> Original | M22: =LARGE($S$35:$S$167,7) -> 9765.374 | N22: =IFERROR(MATCH(M22,$S$35:$S$167,0),0) -> 126
B23: =IF(AND(M23>0,N23>0),8,"") -> 8 | C23: =IF(AND(M23>0,N23>0),INDEX($B$35:$B$167,N23),"") -> Install Sinusoidal Rumble Strip | D23: =IF(AND(M23>0,N23>0),INDEX($C$35:$C$167,N23),"") -> CM: Centerline Rumble Strips (Two-Lane Roads) | E23: =IF(AND(M23>0,N23>0),TEXT(INDEX($D$35:$D$167,N23)/100,"0.0%"),"") -> 57.0% | F23: =IF(AND(M23>0,N23>0),INDEX($E$35:$E$167,N23),"") -> 0.43 | G23: =IF(AND(M23>0,N23>0),IF(INDEX($F$35:$F$167,N23)<=0,"NR",INDEX($F$35:$F$167,N23)),"") -> 5 | H23: =IF(AND(M23>0,N23>0),INDEX($Z$35:$Z$167,N23),"") -> All crashes / Only: Other | I23: =IF(AND(M23>0,N23>0),INDEX($AA$35:$AA$167,N23),"") -> #REF! | J23: =IF(AND(M23>0,N23>0),INDEX($R$35:$R$167,N23),"") -> 97 | K23: =IF(AND(M23>0,N23>0),INDEX($T$35:$T$167,N23),"") -> Added | M23: =LARGE($S$35:$S$167,8) -> 9759.453 | N23: =IFERROR(MATCH(M23,$S$35:$S$167,0),0) -> 47
B24: =IF(AND(M24>0,N24>0),9,"") -> 9 | C24: =IF(AND(M24>0,N24>0),INDEX($B$35:$B$167,N24),"") -> Improve Pavement Friction (Microsurfacing) | D24: =IF(AND(M24>0,N24>0),INDEX($C$35:$C$167,N24),"") -> CM: Pavement Friction Management | E24: =IF(AND(M24>0,N24>0),TEXT(INDEX($D$35:$D$167,N24)/100,"0.0%"),"") -> 56.0% | F24: =IF(AND(M24>0,N24>0),INDEX($E$35:$E$167,N24),"") -> 0.44 | G24: =IF(AND(M24>0,N24>0),IF(INDEX($F$35:$F$167,N24)<=0,"NR",INDEX($F$35:$F$167,N24)),"") -> 4 | H24: =IF(AND(M24>0,N24>0),INDEX($Z$35:$Z$167,N24),"") -> All crashes / Only: Run off road | I24: =IF(AND(M24>0,N24>0),INDEX($AA$35:$AA$167,N24),"") -> #REF! | J24: =IF(AND(M24>0,N24>0),INDEX($R$35:$R$167,N24),"") -> 97 | K24: =IF(AND(M24>0,N24>0),INDEX($T$35:$T$167,N24),"") -> Added | M24: =LARGE($S$35:$S$167,9) -> 9757.869 | N24: =IFERROR(MATCH(M24,$S$35:$S$167,0),0) -> 131
B25: =IF(AND(M25>0,N25>0),10,"") -> 10 | C25: =IF(AND(M25>0,N25>0),INDEX($B$35:$B$167,N25),"") -> Install Cable Median Barrier (High Tension) | D25: =IF(AND(M25>0,N25>0),INDEX($C$35:$C$167,N25),"") -> CM: Median Barriers | E25: =IF(AND(M25>0,N25>0),TEXT(INDEX($D$35:$D$167,N25)/100,"0.0%"),"") -> 53.0% | F25: =IF(AND(M25>0,N25>0),INDEX($E$35:$E$167,N25),"") -> 0.47 | G25: =IF(AND(M25>0,N25>0),IF(INDEX($F$35:$F$167,N25)<=0,"NR",INDEX($F$35:$F$167,N25)),"") -> 4 | H25: =IF(AND(M25>0,N25>0),INDEX($Z$35:$Z$167,N25),"") -> Fatal & injury only / Only: Other | I25: =IF(AND(M25>0,N25>0),INDEX($AA$35:$AA$167,N25),"") -> #REF! | J25: =IF(AND(M25>0,N25>0),INDEX($R$35:$R$167,N25),"") -> 97 | K25: =IF(AND(M25>0,N25>0),INDEX($T$35:$T$167,N25),"") -> Added | M25: =LARGE($S$35:$S$167,10) -> 9754.946 | N25: =IFERROR(MATCH(M25,$S$35:$S$167,0),0) -> 54
B26: =IF(AND(M26>0,N26>0),11,"") -> 11 | C26: =IF(AND(M26>0,N26>0),INDEX($B$35:$B$167,N26),"") -> Improve Pavement Friction (Diamond Grinding) | D26: =IF(AND(M26>0,N26>0),INDEX($C$35:$C$167,N26),"") -> CM: Pavement Friction Management | E26: =IF(AND(M26>0,N26>0),TEXT(INDEX($D$35:$D$167,N26)/100,"0.0%"),"") -> 52.0% | F26: =IF(AND(M26>0,N26>0),INDEX($E$35:$E$167,N26),"") -> 0.48 | G26: =IF(AND(M26>0,N26>0),IF(INDEX($F$35:$F$167,N26)<=0,"NR",INDEX($F$35:$F$167,N26)),"") -> 4 | H26: =IF(AND(M26>0,N26>0),INDEX($Z$35:$Z$167,N26),"") -> All crashes / Only: Wet road | I26: =IF(AND(M26>0,N26>0),INDEX($AA$35:$AA$167,N26),"") -> #REF! | J26: =IF(AND(M26>0,N26>0),INDEX($R$35:$R$167,N26),"") -> 97 | K26: =IF(AND(M26>0,N26>0),INDEX($T$35:$T$167,N26),"") -> Added | M26: =LARGE($S$35:$S$167,11) -> 9753.868 | N26: =IFERROR(MATCH(M26,$S$35:$S$167,0),0) -> 132
B27: =IF(AND(M27>0,N27>0),12,"") -> 12 | C27: =IF(AND(M27>0,N27>0),INDEX($B$35:$B$167,N27),"") -> Install Centerline Rumble Strips | D27: =IF(AND(M27>0,N27>0),INDEX($C$35:$C$167,N27),"") -> CM: Centerline Rumble Strips (Two-Lane Roads) | E27: =IF(AND(M27>0,N27>0),TEXT(INDEX($D$35:$D$167,N27)/100,"0.0%"),"") -> 49.0% | F27: =IF(AND(M27>0,N27>0),INDEX($E$35:$E$167,N27),"") -> 0.51 | G27: =IF(AND(M27>0,N27>0),IF(INDEX($F$35:$F$167,N27)<=0,"NR",INDEX($F$35:$F$167,N27)),"") -> 5 | H27: =IF(AND(M27>0,N27>0),INDEX($Z$35:$Z$167,N27),"") -> All crashes / Only: Head on,Sideswipe | I27: =IF(AND(M27>0,N27>0),INDEX($AA$35:$AA$167,N27),"") -> #REF! | J27: =IF(AND(M27>0,N27>0),INDEX($R$35:$R$167,N27),"") -> 97 | K27: =IF(AND(M27>0,N27>0),INDEX($T$35:$T$167,N27),"") -> Added | M27: =LARGE($S$35:$S$167,12) -> 9751.452 | N27: =IFERROR(MATCH(M27,$S$35:$S$167,0),0) -> 48
B28: =IF(AND(M28>0,N28>0),13,"") -> 13 | C28: =IF(AND(M28>0,N28>0),INDEX($B$35:$B$167,N28),"") -> Install Centerline Rumble Strips On Tangent Sections | D28: =IF(AND(M28>0,N28>0),INDEX($C$35:$C$167,N28),"") -> CM: Centerline Rumble Strips (Two-Lane Roads) | E28: =IF(AND(M28>0,N28>0),TEXT(INDEX($D$35:$D$167,N28)/100,"0.0%"),"") -> 49.0% | F28: =IF(AND(M28>0,N28>0),INDEX($E$35:$E$167,N28),"") -> 0.51 | G28: =IF(AND(M28>0,N28>0),IF(INDEX($F$35:$F$167,N28)<=0,"NR",INDEX($F$35:$F$167,N28)),"") -> 5 | H28: =IF(AND(M28>0,N28>0),INDEX($Z$35:$Z$167,N28),"") -> All crashes / Only: Head on,Sideswipe | I28: =IF(AND(M28>0,N28>0),INDEX($AA$35:$AA$167,N28),"") -> #REF! | J28: =IF(AND(M28>0,N28>0),INDEX($R$35:$R$167,N28),"") -> 97 | K28: =IF(AND(M28>0,N28>0),INDEX($T$35:$T$167,N28),"") -> Added | M28: =LARGE($S$35:$S$167,13) -> 9751.451 | N28: =IFERROR(MATCH(M28,$S$35:$S$167,0),0) -> 49
B29: =IF(AND(M29>0,N29>0),14,"") -> 14 | C29: =IF(AND(M29>0,N29>0),INDEX($B$35:$B$167,N29),"") -> Install Centerline Rumble Strips On Horizontal Curves | D29: =IF(AND(M29>0,N29>0),INDEX($C$35:$C$167,N29),"") -> CM: Centerline Rumble Strips (Two-Lane Roads) | E29: =IF(AND(M29>0,N29>0),TEXT(INDEX($D$35:$D$167,N29)/100,"0.0%"),"") -> 47.0% | F29: =IF(AND(M29>0,N29>0),INDEX($E$35:$E$167,N29),"") -> 0.53 | G29: =IF(AND(M29>0,N29>0),IF(INDEX($F$35:$F$167,N29)<=0,"NR",INDEX($F$35:$F$167,N29)),"") -> 5 | H29: =IF(AND(M29>0,N29>0),INDEX($Z$35:$Z$167,N29),"") -> All crashes / Only: Head on,Sideswipe | I29: =IF(AND(M29>0,N29>0),INDEX($AA$35:$AA$167,N29),"") -> #REF! | J29: =IF(AND(M29>0,N29>0),INDEX($R$35:$R$167,N29),"") -> 97 | K29: =IF(AND(M29>0,N29>0),INDEX($T$35:$T$167,N29),"") -> Added | M29: =LARGE($S$35:$S$167,14) -> 9749.45 | N29: =IFERROR(MATCH(M29,$S$35:$S$167,0),0) -> 50
B30: =IF(AND(M30>0,N30>0),15,"") -> 15 | C30: =IF(AND(M30>0,N30>0),INDEX($B$35:$B$167,N30),"") -> Install W-Beam Guardrail | D30: =IF(AND(M30>0,N30>0),INDEX($C$35:$C$167,N30),"") -> CM: Roadside Barriers (Guardrail) | E30: =IF(AND(M30>0,N30>0),TEXT(INDEX($D$35:$D$167,N30)/100,"0.0%"),"") -> 47.0% | F30: =IF(AND(M30>0,N30>0),INDEX($E$35:$E$167,N30),"") -> 0.53 | G30: =IF(AND(M30>0,N30>0),IF(INDEX($F$35:$F$167,N30)<=0,"NR",INDEX($F$35:$F$167,N30)),"") -> 4 | H30: =IF(AND(M30>0,N30>0),INDEX($Z$35:$Z$167,N30),"") -> Fatal & injury only / Only: Nighttime,Run off road | I30: =IF(AND(M30>0,N30>0),INDEX($AA$35:$AA$167,N30),"") -> #REF! | J30: =IF(AND(M30>0,N30>0),INDEX($R$35:$R$167,N30),"") -> 97 | K30: =IF(AND(M30>0,N30>0),INDEX($T$35:$T$167,N30),"") -> Added | M30: =LARGE($S$35:$S$167,15) -> 9748.942 | N30: =IFERROR(MATCH(M30,$S$35:$S$167,0),0) -> 58
B33: v engine (hidden) v
A34: idx | B34: Treatment | C34: CM | D34: CRF | E34: CMF | F34: Star | G34: AADTmin | H34: AADTmax | I34: Area | J34: Loc | K34: Control | L34: Tags | M34: crashSc | N34: areaSc | O34: locSc | P34: ctrlSc | Q34: aadtSc | R34: Fit | S34: Priority | T34: Source | U34: RoadCls | V34: roadSc | W34: Use | X34: SevScope | Y34: sevSc | Z34: Scope text | AA34: Caution
A35: 1 | B35: =Treatments!A3 -> Install Automated Section Speed Enforcement System | C35: =Treatments!B3 -> CM: Appropriate Speed Limits for All Road Users | D35: =Treatments!Q3 -> 36.8 | E35: =Treatments!P3 -> 0.632 | F35: =IF(ISNUMBER(Treatments!N3),Treatments!N3,0) -> 5 | G35: =IF(ISNUMBER(Treatments!U3),Treatments!U3,"") | H35: =IF(ISNUMBER(Treatments!V3),Treatments!V3,"") | I35: Urban | J35: Roadway Segment | K35: Any | L35: |All|Speeding| | M35: =IF(ISNUMBER(SEARCH("|"&$C$7&"|",L35)),45,IF(ISNUMBER(SEARCH("|All|",L35)),18,0)) -> 18 | N35: =IF(OR($C$4="Any",I35="All"),12,IF(ISNUMBER(SEARCH($C$4,I35)),12,0)) -> 12 | O35: =IF(OR($C$5="Any",J35="Any",J35=$C$5),13,0) -> 13 | P35: =IF(OR($C$6="Any",K35="Any",K35=$C$6),10,0) -> 10 | Q35: =IF($C$8="",4,IF(AND(ISNUMBER(G35),ISNUMBER(H35)),IF(AND($C$8>=G35,$C$8<=H35),7,0),4)) -> 4 | R35: =M35+N35+O35+P35+Q35+V35+Y35 -> 70 | S35: =IF(OR(M35=0,W35=0),-A35,R35*100+D35+F35*0.5-A35*0.001) -> 7039.299 | T35: =Treatments!M3 -> Original | U35: Freeway/Expressway | V35: =IF(OR($C$11="Any",U35="Any",U35=$C$11),8,0) -> 8 | W35: =IF(LEFT(Treatments!AD3,3)="Yes",1,0) -> 1 | X35: =Treatments!AE3 -> Fatal & injury only | Y35: =IF($C$12="Any",5,IF($C$12=X35,5,IF(AND($C$12="Fatal & injury only",X35="All crashes"),3,0))) -> 5 | Z35: =Treatments!AE3&" / "&Treatments!AF3 -> Fatal & injury only / All crash types | AA35: =IF(Treatments!#REF!="","",Treatments!#REF!) -> #REF!
A36: 2 | B36: =Treatments!A4 -> Implement Automated Speed Enforcement Cameras | C36: =Treatments!B4 -> CM: Appropriate Speed Limits for All Road Users | D36: =Treatments!Q4 -> 54 | E36: =Treatments!P4 -> 0.46 | F36: =IF(ISNUMBER(Treatments!N4),Treatments!N4,0) -> 4 | G36: =IF(ISNUMBER(Treatments!U4),Treatments!U4,"") | H36: =IF(ISNUMBER(Treatments!V4),Treatments!V4,"") | I36: Urban | J36: Roadway Segment | K36: Any | L36: |All|Speeding| | M36: =IF(ISNUMBER(SEARCH("|"&$C$7&"|",L36)),45,IF(ISNUMBER(SEARCH("|All|",L36)),18,0)) -> 18 | N36: =IF(OR($C$4="Any",I36="All"),12,IF(ISNUMBER(SEARCH($C$4,I36)),12,0)) -> 12 | O36: =IF(OR($C$5="Any",J36="Any",J36=$C$5),13,0) -> 13 | P36: =IF(OR($C$6="Any",K36="Any",K36=$C$6),10,0) -> 10 | Q36: =IF($C$8="",4,IF(AND(ISNUMBER(G36),ISNUMBER(H36)),IF(AND($C$8>=G36,$C$8<=H36),7,0),4)) -> 4 | R36: =M36+N36+O36+P36+Q36+V36+Y36 -> 70 | S36: =IF(OR(M36=0,W36=0),-A36,R36*100+D36+F36*0.5-A36*0.001) -> 7055.998 | T36: =Treatments!M4 -> Original | U36: Arterial/Collector | V36: =IF(OR($C$11="Any",U36="Any",U36=$C$11),8,0) -> 8 | W36: =IF(LEFT(Treatments!AD4,3)="Yes",1,0) -> 1 | X36: =Treatments!AE4 -> All crashes | Y36: =IF($C$12="Any",5,IF($C$12=X36,5,IF(AND($C$12="Fatal & injury only",X36="All crashes"),3,0))) -> 5 | Z36: =Treatments!AE4&" / "&Treatments!AF4 -> All crashes / All crash types | AA36: =IF(Treatments!#REF!="","",Treatments!#REF!) -> #REF!
A37: 3 | B37: =Treatments!A5 -> Install Variable Speed Limit (Vsl) | C37: =Treatments!B5 -> CM: Appropriate Speed Limits for All Road Users | D37: =Treatments!Q5 -> 34 | E37: =Treatments!P5 -> 0.66 | F37: =IF(ISNUMBER(Treatments!N5),Treatments!N5,0) -> 3 | G37: =IF(ISNUMBER(Treatments!U5),Treatments!U5,"") -> 10194 | H37: =IF(ISNUMBER(Treatments!V5),Treatments!V5,"") -> 11090 | I37: All | J37: Roadway Segment | K37: Any | L37: |All|Speeding| | M37: =IF(ISNUMBER(SEARCH("|"&$C$7&"|",L37)),45,IF(ISNUMBER(SEARCH("|All|",L37)),18,0)) -> 18 | N37: =IF(OR($C$4="Any",I37="All"),12,IF(ISNUMBER(SEARCH($C$4,I37)),12,0)) -> 12 | O37: =IF(OR($C$5="Any",J37="Any",J37=$C$5),13,0) -> 13 | P37: =IF(OR($C$6="Any",K37="Any",K37=$C$6),10,0) -> 10 | Q37: =IF($C$8="",4,IF(AND(ISNUMBER(G37),ISNUMBER(H37)),IF(AND($C$8>=G37,$C$8<=H37),7,0),4)) -> 4 | R37: =M37+N37+O37+P37+Q37+V37+Y37 -> 70 | S37: =IF(OR(M37=0,W37=0),-A37,R37*100+D37+F37*0.5-A37*0.001) -> 7035.497 | T37: =Treatments!M5 -> Original | U37: Freeway/Expressway | V37: =IF(OR($C$11="Any",U37="Any",U37=$C$11),8,0) -> 8 | W37: =IF(LEFT(Treatments!AD5,3)="Yes",1,0) -> 1 | X37: =Treatments!AE5 -> All crashes | Y37: =IF($C$12="Any",5,IF($C$12=X37,5,IF(AND($C$12="Fatal & injury only",X37="All crashes"),3,0))) -> 5 | Z37: =Treatments!AE5&" / "&Treatments!AF5 -> All crashes / All crash types | AA37: =IF(Treatments!#REF!="","",Treatments!#REF!) -> #REF!
A38: 4 | B38: =Treatments!A6 -> Install Variable Speed Limit | C38: =Treatments!B6 -> CM: Appropriate Speed Limits for All Road Users | D38: =Treatments!Q6 -> 13.9 | E38: =Treatments!P6 -> 0.861 | F38: =IF(ISNUMBER(Treatments!N6),Treatments!N6,0) -> 4 | G38: =IF(ISNUMBER(Treatments!U6),Treatments!U6,"") -> 53729 | H38: =IF(ISNUMBER(Treatments!V6),Treatments!V6,"") -> 282619 | I38: All | J38: Roadway Segment | K38: Any | L38: |All|Speeding| | M38: =IF(ISNUMBER(SEARCH("|"&$C$7&"|",L38)),45,IF(ISNUMBER(SEARCH("|All|",L38)),18,0)) -> 18 | N38: =IF(OR($C$4="Any",I38="All"),12,IF(ISNUMBER(SEARCH($C$4,I38)),12,0)) -> 12 | O38: =IF(OR($C$5="Any",J38="Any",J38=$C$5),13,0) -> 13 | P38: =IF(OR($C$6="Any",K38="Any",K38=$C$6),10,0) -> 10 | Q38: =IF($C$8="",4,IF(AND(ISNUMBER(G38),ISNUMBER(H38)),IF(AND($C$8>=G38,$C$8<=H38),7,0),4)) -> 4 | R38: =M38+N38+O38+P38+Q38+V38+Y38 -> 70 | S38: =IF(OR(M38=0,W38=0),-A38,R38*100+D38+F38*0.5-A38*0.001) -> 7015.896 | T38: =Treatments!M6 -> Added | U38: Freeway/Expressway | V38: =IF(OR($C$11="Any",U38="Any",U38=$C$11),8,0) -> 8 | W38: =IF(LEFT(Treatments!AD6,3)="Yes",1,0) -> 1 | X38: =Treatments!AE6 -> Fatal & injury only | Y38: =IF($C$12="Any",5,IF($C$12=X38,5,IF(AND($C$12="Fatal & injury only",X38="All crashes"),3,0))) -> 5 | Z38: =Treatments!AE6&" / "&Treatments!AF6 -> Fatal & injury only / All crash types | AA38: =IF(Treatments!#REF!="","",Treatments!#REF!) -> #REF!
A39: 5 | B39: =Treatments!A7 -> Install Dynamic Speed Feedback Sign | C39: =Treatments!B7 -> CM: Appropriate Speed Limits for All Road Users | D39: =Treatments!Q7 -> 7 | E39: =Treatments!P7 -> 0.93 | F39: =IF(ISNUMBER(Treatments!N7),Treatments!N7,0) -> 4 | G39: =IF(ISNUMBER(Treatments!U7),Treatments!U7,"") -> 400 | H39: =IF(ISNUMBER(Treatments!V7),Treatments!V7,"") -> 8400 | I39: Rural | J39: Roadway Segment | K39: Any | L39: |All|Speeding| | M39: =IF(ISNUMBER(SEARCH("|"&$C$7&"|",L39)),45,IF(ISNUMBER(SEARCH("|All|",L39)),18,0)) -> 18 | N39: =IF(OR($C$4="Any",I39="All"),12,IF(ISNUMBER(SEARCH($C$4,I39)),12,0)) -> 12 | O39: =IF(OR($C$5="Any",J39="Any",J39=$C$5),13,0) -> 13 | P39: =IF(OR($C$6="Any",K39="Any",K39=$C$6),10,0) -> 10 | Q39: =IF($C$8="",4,IF(AND(ISNUMBER(G39),ISNUMBER(H39)),IF(AND($C$8>=G39,$C$8<=H39),7,0),4)) -> 4 | R39: =M39+N39+O39+P39+Q39+V39+Y39 -> 70 | S39: =IF(OR(M39=0,W39=0),-A39,R39*100+D39+F39*0.5-A39*0.001) -> 7008.995 | T39: =Treatments!M7 -> Added | U39: Any | V39: =IF(OR($C$11="Any",U39="Any",U39=$C$11),8,0) -> 8 | W39: =IF(LEFT(Treatments!AD7,3)="Yes",1,0) -> 1 | X39: =Treatments!AE7 -> All crashes | Y39: =IF($C$12="Any",5,IF($C$12=X39,5,IF(AND($C$12="Fatal & injury only",X39="All crashes"),3,0))) -> 5 | Z39: =Treatments!AE7&" / "&Treatments!AF7 -> All crashes / All crash types | AA39: =IF(Treatments!#REF!="","",Treatments!#REF!) -> #REF!
A40: 6 | B40: =Treatments!A8 -> Install Automated Section Speed Enforcement System | C40: =Treatments!B8 -> CM: Appropriate Speed Limits for All Road Users | D40: =Treatments!Q8 -> 43.7 | E40: =Treatments!P8 -> 0.563 | F40: =IF(ISNUMBER(Treatments!N8),Treatments!N8,0) -> 5 | G40: =IF(ISNUMBER(Treatments!U8),Treatments!U8,"") | H40: =IF(ISNUMBER(Treatments!V8),Treatments!V8,"") | I40: Urban | J40: Roadway Segment | K40: Any | L40: |Speeding| | M40: =IF(ISNUMBER(SEARCH("|"&$C$7&"|",L40)),45,IF(ISNUMBER(SEARCH("|All|",L40)),18,0)) -> 0 | N40: =IF(OR($C$4="Any",I40="All"),12,IF(ISNUMBER(SEARCH($C$4,I40)),12,0)) -> 12 | O40: =IF(OR($C$5="Any",J40="Any",J40=$C$5),13,0) -> 13 | P40: =IF(OR($C$6="Any",K40="Any",K40=$C$6),10,0) -> 10 | Q40: =IF($C$8="",4,IF(AND(ISNUMBER(G40),ISNUMBER(H40)),IF(AND($C$8>=G40,$C$8<=H40),7,0),4)) -> 4 | R40: =M40+N40+O40+P40+Q40+V40+Y40 -> 52 | S40: =IF(OR(M40=0,W40=0),-A40,R40*100+D40+F40*0.5-A40*0.001) -> -6 | T40: =Treatments!M8 -> Added | U40: Freeway/Expressway | V40: =IF(OR($C$11="Any",U40="Any",U40=$C$11),8,0) -> 8 | W40: =IF(LEFT(Treatments!AD8,3)="Yes",1,0) -> 1 | X40: =Treatments!AE8 -> All crashes | Y40: =IF($C$12="Any",5,IF($C$12=X40,5,IF(AND($C$12="Fatal & injury only",X40="All crashes"),3,0))) -> 5 | Z40: =Treatments!AE8&" / "&Treatments!AF8 -> All crashes / Only: Single vehicle | AA40: =IF(Treatments!#REF!="","",Treatments!#REF!) -> #REF!
A41: 7 | B41: =Treatments!A9 -> Implement Mobile Automated Speed Enforcement System | C41: =Treatments!B9 -> CM: Appropriate Speed Limits for All Road Users | D41: =Treatments!Q9 -> 20.1 | E41: =Treatments!P9 -> 0.799 | F41: =IF(ISNUMBER(Treatments!N9),Treatments!N9,0) -> 5 | G41: =IF(ISNUMBER(Treatments!U9),Treatments!U9,"") -> 2079 | H41: =IF(ISNUMBER(Treatments!V9),Treatments!V9,"") -> 22960 | I41: Urban | J41: Roadway Segment | K41: Any | L41: |All|Speeding| | M41: =IF(ISNUMBER(SEARCH("|"&$C$7&"|",L41)),45,IF(ISNUMBER(SEARCH("|All|",L41)),18,0)) -> 18 | N41: =IF(OR($C$4="Any",I41="All"),12,IF(ISNUMBER(SEARCH($C$4,I41)),12,0)) -> 12 | O41: =IF(OR($C$5="Any",J41="Any",J41=$C$5),13,0) -> 13 | P41: =IF(OR($C$6="Any",K41="Any",K41=$C$6),10,0) -> 10 | Q41: =IF($C$8="",4,IF(AND(ISNUMBER(G41),ISNUMBER(H41)),IF(AND($C$8>=G41,$C$8<=H41),7,0),4)) -> 4 | R41: =M41+N41+O41+P41+Q41+V41+Y41 -> 70 | S41: =IF(OR(M41=0,W41=0),-A41,R41*100+D41+F41*0.5-A41*0.001) -> 7022.593 | T41: =Treatments!M9 -> Added | U41: Arterial/Collector | V41: =IF(OR($C$11="Any",U41="Any",U41=$C$11),8,0) -> 8 | W41: =IF(LEFT(Treatments!AD9,3)="Yes",1,0) -> 1 | X41: =Treatments!AE9 -> Fatal & injury only | Y41: =IF($C$12="Any",5,IF($C$12=X41,5,IF(AND($C$12="Fatal & injury only",X41="All crashes"),3,0))) -> 5 | Z41: =Treatments!AE9&" / "&Treatments!AF9 -> Fatal & injury only / All crash types | AA41: =IF(Treatments!#REF!="","",Treatments!#REF!) -> #REF!
A42: 8 | B42: =Treatments!A10 -> Implement Automated Speed Enforcement Cameras | C42: =Treatments!B10 -> CM: Appropriate Speed Limits for All Road Users | D42: =Treatments!Q10 -> 67 | E42: =Treatments!P10 -> 0.33 | F42: =IF(ISNUMBER(Treatments!N10),Treatments!N10,0) -> 4 | G42: =IF(ISNUMBER(Treatments!U10),Treatments!U10,"") | H42: =IF(ISNUMBER(Treatments!V10),Treatments!V10,"") | I42: Urban | J42: Roadway Segment | K42: Any | L42: |Speeding| | M42: =IF(ISNUMBER(SEARCH("|"&$C$7&"|",L42)),45,IF(ISNUMBER(SEARCH("|All|",L42)),18,0)) -> 0 | N42: =IF(OR($C$4="Any",I42="All"),12,IF(ISNUMBER(SEARCH($C$4,I42)),12,0)) -> 12 | O42: =IF(OR($C$5="Any",J42="Any",J42=$C$5),13,0) -> 13 | P42: =IF(OR($C$6="Any",K42="Any",K42=$C$6),10,0) -> 10 | Q42: =IF($C$8="",4,IF(AND(ISNUMBER(G42),ISNUMBER(H42)),IF(AND($C$8>=G42,$C$8<=H42),7,0),4)) -> 4 | R42: =M42+N42+O42+P42+Q42+V42+Y42 -> 52 | S42: =IF(OR(M42=0,W42=0),-A42,R42*100+D42+F42*0.5-A42*0.001) -> -8 | T42: =Treatments!M10 -> Added | U42: Arterial/Collector | V42: =IF(OR($C$11="Any",U42="Any",U42=$C$11),8,0) -> 8 | W42: =IF(LEFT(Treatments!AD10,3)="Yes",1,0) -> 1 | X42: =Treatments!AE10 -> PDO only | Y42: =IF($C$12="Any",5,IF($C$12=X42,5,IF(AND($C$12="Fatal & injury only",X42="All crashes"),3,0))) -> 5 | Z42: =Treatments!AE10&" / "&Treatments!AF10 -> PDO only / Only: Single vehicle | AA42: =IF(Treatments!#REF!="","",Treatments!#REF!) -> #REF!
A43: 9 | B43: =Treatments!A11 -> Install Automated Section Speed Enforcement System On Curves | C43: =Treatments!B11 -> CM: Appropriate Speed Limits for All Road Users | D43: =Treatments!Q11 -> 43 | E43: =Treatments!P11 -> 0.57 | F43: =IF(ISNUMBER(Treatments!N11),Treatments!N11,0) -> 4 | G43: =IF(ISNUMBER(Treatments!U11),Treatments!U11,"") -> 23000 | H43: =IF(ISNUMBER(Treatments!V11),Treatments!V11,"") -> 42000 | I43: All | J43: Roadway Segment | K43: Any | L43: |All|Speeding| | M43: =IF(ISNUMBER(SEARCH("|"&$C$7&"|",L43)),45,IF(ISNUMBER(SEARCH("|All|",L43)),18,0)) -> 18 | N43: =IF(OR($C$4="Any",I43="All"),12,IF(ISNUMBER(SEARCH($C$4,I43)),12,0)) -> 12 | O43: =IF(OR($C$5="Any",J43="Any",J43=$C$5),13,0) -> 13 | P43: =IF(OR($C$6="Any",K43="Any",K43=$C$6),10,0) -> 10 | Q43: =IF($C$8="",4,IF(AND(ISNUMBER(G43),ISNUMBER(H43)),IF(AND($C$8>=G43,$C$8<=H43),7,0),4)) -> 4 | R43: =M43+N43+O43+P43+Q43+V43+Y43 -> 70 | S43: =IF(OR(M43=0,W43=0),-A43,R43*100+D43+F43*0.5-A43*0.001) -> 7044.991 | T43: =Treatments!M11 -> Added | U43: Freeway/Expressway | V43: =IF(OR($C$11="Any",U43="Any",U43=$C$11),8,0) -> 8 | W43: =IF(LEFT(Treatments!AD11,3)="Yes",1,0) -> 1 | X43: =Treatments!AE11 -> All crashes | Y43: =IF($C$12="Any",5,IF($C$12=X43,5,IF(AND($C$12="Fatal & injury only",X43="All crashes"),3,0))) -> 5 | Z43: =Treatments!AE11&" / "&Treatments!AF11 -> All crashes / All crash types | AA43: =IF(Treatments!#REF!="","",Treatments!#REF!) -> #REF!
A44: 10 | B44: =Treatments!A12 -> Convert Traditional Or Flush Buffered Bike Lane To Sbl With Flexi-Posts | C44: =Treatments!B12 -> CM: Bicycle Lanes | D44: =Treatments!Q12 -> 53.2 | E44: =Treatments!P12 -> 0.468 | F44: =IF(ISNUMBER(Treatments!N12),Treatments!N12,0) -> 4 | G44: =IF(ISNUMBER(Treatments!U12),Treatments!U12,"") | H44: =IF(ISNUMBER(Treatments!V12),Treatments!V12,"") | I44: Urban | J44: Roadway Segment | K44: Any | L44: |Bicycle| | M44: =IF(ISNUMBER(SEARCH("|"&$C$7&"|",L44)),45,IF(ISNUMBER(SEARCH("|All|",L44)),18,0)) -> 0 | N44: =IF(OR($C$4="Any",I44="All"),12,IF(ISNUMBER(SEARCH($C$4,I44)),12,0)) -> 12 | O44: =IF(OR($C$5="Any",J44="Any",J44=$C$5),13,0) -> 13 | P44: =IF(OR($C$6="Any",K44="Any",K44=$C$6),10,0) -> 10 | Q44: =IF($C$8="",4,IF(AND(ISNUMBER(G44),ISNUMBER(H44)),IF(AND($C$8>=G44,$C$8<=H44),7,0),4)) -> 4 | R44: =M44+N44+O44+P44+Q44+V44+Y44 -> 52 | S44: =IF(OR(M44=0,W44=0),-A44,R44*100+D44+F44*0.5-A44*0.001) -> -10 | T44: =Treatments!M12 -> Original | U44: Any | V44: =IF(OR($C$11="Any",U44="Any",U44=$C$11),8,0) -> 8 | W44: =IF(LEFT(Treatments!AD12,3)="Yes",1,0) -> 1 | X44: =Treatments!AE12 -> All crashes | Y44: =IF($C$12="Any",5,IF($C$12=X44,5,IF(AND($C$12="Fatal & injury only",X44="All crashes"),3,0))) -> 5 | Z44: =Treatments!AE12&" / "&Treatments!AF12 -> All crashes / Only: Vehicle/bicycle | AA44: =IF(Treatments!#REF!="","",Treatments!#REF!) -> #REF!
...

Sheet Countermeasures
A1: COUNTERMEASURES
A2: Area | B2: Countermeasure | C2: Derived filter | D2: Area type | E2: Intersection? | F2: Crash type(s) | G2: Traffic control | H2: Other site conditions | I2: Exclusions | J2: Crash criteria | K2: # Treat.
A3: Speed Management | B3: CM: Appropriate Speed Limits for All Road Users | C3: Speeding Related = Yes | D3: Any | E3: Any | F3: Speeding-related (any crash type) | G3: Any | H3: - | I3: Too Fast for Conditions (3) is NOT used | J3: Speed Related = Racing (1) or Exceeded Speed Limit (2) | K3: =COUNTIF(Treatments!B:B,B3) -> 9
A4: Pedestrian/Bicyclist | B4: CM: Bicycle Lanes | C4: Vulnerable Road User Related = Yes | D4: Any | E4: Any | F4: Bicycle | G4: Any | H4: - | I4: - | J4: Non-Motorist Unit Type = Bicyclist (66) or Other Cyclist (67) or First Harmful Event = Pedalcycle (25) or Unit Type = Motorized Bike (40) | K4: =COUNTIF(Treatments!B:B,B4) -> 8
A5: Pedestrian/Bicyclist | B5: CM: Crosswalk Visibility Enhancements | C5: Pedestrian Related = Yes or Vulnerable Road User Related = Yes and Intersection Related = Yes | D5: Urban / Suburban | E5: Yes | F5: Pedestrian, Bicycle | G5: Any | H5: - | I5: - | J5: ( First Harmful Event = Pedestrian (26) or Pedalcycle (25) or Non-Motorist Unit Type = Bicyclist (66) or Other Cyclist (67) ) and Relation to Junction = Intersection or Related (05) | K5: =COUNTIF(Treatments!B:B,B5) -> 3
A6: Pedestrian/Bicyclist | B6: CM: Leading Pedestrian Interval | C6: Pedestrian Related = Yes and Intersection Related = Yes | D6: Urban / Suburban | E6: Yes | F6: Pedestrian, Bicycle | G6: Signalized | H6: Turning vehicle | I6: - | J6: Relation to Junction = Intersection or Related (05) and Traffic Control Device = Traffic Control Signal (17) and First Harmful Event = Pedestrian (26) or Pedalcycle (25) and VEHICLE Action Prior to Impact = Turning Left (10) or Turning Right (11) | K6: =COUNTIF(Treatments!B:B,B6) -> 2
A7: Pedestrian/Bicyclist | B7: CM: Medians and Pedestrian Refuge Islands in Urban and Suburban Areas | C7: Pedestrian Related = Yes and Intersection Related = No | D7: Urban / Suburban | E7: No (midblock) | F7: Pedestrian | G7: Any | H7: Through Lanes >= 4 | I7: Bicyclists excluded | J7: First Harmful Event = Pedestrian (26) and Relation to Junction = Non-Junction (00) and Through Lanes >= 4 | K7: =COUNTIF(Treatments!B:B,B7) -> 3
A8: Pedestrian/Bicyclist | B8: CM: Pedestrian Hybrid Beacons | C8: Pedestrian Related = Yes and Intersection Related = No | D8: Urban / Suburban | E8: No (midblock) | F8: Pedestrian, Bicycle | G8: Uncontrolled (no signal) | H8: Through Lanes >= 2, Speed Limit >= 35 | I8: - | J8: First Harmful Event = Pedestrian (26) or Pedalcycle (25) and Relation to Junction = Non-Junction (00) and Traffic Control Device is not Traffic Control Signal (17) and Through Lanes >= 2 and Speed Limit >= 35 | K8: =COUNTIF(Treatments!B:B,B8) -> 3
A9: Pedestrian/Bicyclist | B9: CM: Rectangular Rapid Flashing Beacons (RRFB) | C9: Pedestrian Related = Yes and Intersection Related = No | D9: Urban / Suburban | E9: No (midblock) | F9: Pedestrian, Bicycle | G9: Uncontrolled (no signal) | H9: - | I9: - | J9: First Harmful Event = Pedestrian (26) or Pedalcycle (25) and Relation to Junction = Non-Junction (00) and Traffic Control Device is not Traffic Control Signal (17) | K9: =COUNTIF(Treatments!B:B,B9) -> 2
A10: Pedestrian/Bicyclist | B10: CM: Road Diets (Roadway Reconfiguration) | C10: Pedestrian Related = Yes | D10: Urban | E10: Any | F10: Rear-end, Head-on, Angle, Pedestrian, Bicycle | G10: Any | H10: Through Lanes = 4 and Trafficway = Two-Way Not Divided | I10: Urban Interstate and Urban Freeway/Expressway excluded | J10: Through Lanes = 4 and Trafficway = Two-Way, Not Divided and road is Urban (exclude Urban Interstate and Urban Freeway/Expressway) and ( Manner of Collision = Front To Rear (10), Front To Front (20), or Angle (80) or First Harmful Event = Pedestrian (26) or Pedalcycle (25) ) | K10: =COUNTIF(Treatments!B:B,B10) -> 3
A11: Pedestrian/Bicyclist | B11: CM: Walkways | C11: Pedestrian Related = Yes and Intersection Related = No | D11: Urban / Suburban | E11: No (midblock) | F11: Pedestrian | G11: Any | H11: Pedestrian walking along the road | I11: - | J11: First Harmful Event = Pedestrian (26) and Relation to Junction = Non-Junction (00) and NON-MOTORIST Action Prior to Impact = Walking Along Roadway With Traffic (27), Against Traffic (28), or Adjacent to Roadway (31) | K11: =COUNTIF(Treatments!B:B,B11) -> 1
A12: Roadway Departure | B12: CM: Enhanced Delineation for Horizontal Curves | C12: Roadway Departure = Yes | D12: Any | E12: No (segment) | F12: Lane departure (run-off-road + cross-centerline) | G12: Any | H12: Alignment = Curve Left (02) or Curve Right (03), or Vehicle Action Prior to Impact = Negotiating a Curve (07) | I12: Pedestrian, bicycle, animal, obstruction-in-roadway and debris crashes excluded | J12: Relation to Junction = Non-Junction (00) and Alignment = Curve Left (02) or Curve Right (03) [or Vehicle Action Prior to Impact = Negotiating a Curve (07)] and Manner of Collision = Not a Collision with Motor Vehicle in Transport (00) and First Harmful Event is not Pedestrian (26) or Pedalcycle (25) and Most Harmful Event is not Animal-Deer (20) or Animal-Not Deer (21) and Contributing Roadway Condition is not Obstruction in Roadway (11) or Debris (10) | K12: =COUNTIF(Treatments!B:B,B12) -> 9
A13: Roadway Departure | B13: CM: Centerline Rumble Strips (Two-Lane Roads) | C13: Lane Departure = Yes and Roadway Departure = No | D13: Rural (studies) / any | E13: No (segment) | F13: Head-on, Sideswipe opposite direction, Cross-centerline | G13: Any | H13: Through Lanes = 2 and Trafficway = Two-Way, Not Divided | I13: Animal crashes excluded | J13: Relation to Junction = Non-Junction (00) and Through Lanes = 2 and Trafficway = Two-Way, Not Divided and ( Manner of Collision = Front To Front (20) or Sideswipe Opposite Direction (40) or Sequence of Events = Cross Centerline (01) ) and Most Harmful Event is not Animal-Deer (20) or Animal-Not Deer (21) | K13: =COUNTIF(Treatments!B:B,B13) -> 5
A14: Roadway Departure | B14: CM: Shoulder Rumble Strips | C14: Roadway Departure = Yes | D14: Rural (studies) / any | E14: No (segment) | F14: Run-off-road (single vehicle) | G14: Any | H14: - | I14: Pedestrian, bicycle, animal, obstruction-in-roadway and debris crashes excluded | J14: Relation to Junction = Non-Junction (00) and Manner of Collision = Not a Collision with Motor Vehicle in Transport (00) and First Harmful Event is not Pedestrian (26) or Pedalcycle (25) and Most Harmful Event is not Animal-Deer (20) or Animal-Not Deer (21) and Contributing Roadway Condition is not Obstruction in Roadway (11) or Debris (10) [optional refinement, NOT a gate: Sequence of Events = Ran Off Road Left (06) or Right (07)] | K14: =COUNTIF(Treatments!B:B,B14) -> 4
... A32: Crosscutting | B32: CM: Pavement Friction Management | C32: Roadway Departure = Yes or Negotiating a Curve | D32: Any | E32: Any | F32: Wet-road, Run-off-road, Curve | G32: Any | H32: Road Surface Condition = Wet (02), Ice/Frost (05), or Slush (04) | I32: Pedestrian, bicycle, animal, obstruction-in-roadway and debris crashes excluded | J32: Road Surface Condition = Wet (02), Ice/Frost (05), or Slush (04) and ( Vehicle Action Prior to Impact = Negotiating a Curve (07) or Manner of Collision = Not a Collision with Motor Vehicle in Transport (00) and First Harmful Event is not Pedestrian (26) or Pedalcycle (25) and Most Harmful Event is not Animal-Deer (20) or Animal-Not Deer (21) and Contributing Roadway Condition is not Obstruction in Roadway (11) or Debris (10) | K32: =COUNTIF(Treatments!B:B,B32) -> 8

Sheet Treatments
A1: TREATMENTS
A2: Treatment | B2: Countermeasure | C2: Default CMF (K) | D2: Default CMF (A) | E2: Default CMF (B) | F2: Default CMF (C) | G2: Default CMF (O) | H2: Default Service Years | I2: Date Added | J2: Added By | K2: Checked By | L2: CMF ID | M2: Source | N2: Star | O2: Area Type | P2: CMF | Q2: CRF % | R2: KABCO Severity | S2: Crash Type (CMF) | T2: Roadway Type | U2: AADT Min | V2: AADT Max | W2: AADT Avg | X2: Intersection / Control | Y2: Speed Limit | Z2: In HSM | AA2: Sample (sites / crashes) | AB2: Study Method | AC2: Background / Notes | AD2: Use? | AE2: Severity scope | AF2: Crash-type scope | AG2: SCDOT applicability check | AH2: Lane departure CMF?
A3: Install Automated Section Speed Enforcement System | B3: CM: Appropriate Speed Limits for All Road Users | C3: 0.632 | D3: 0.632 | E3: 0.632 | F3: 0.632 | G3: 0.632 | H3: 20 | L3: CMF: 7718 | M3: Original | N3: 5 | O3: Urban | P3: =C3 -> 0.632 | Q3: =IF(ISNUMBER(P3),ROUND((1-P3)*100,1),"NR") -> 36.8 | R3: K (fatal),A (serious injury),B (minor injury),C (possible injury) | S3: All | T3: Principal Arterial Other Freeways and Expressways | U3: NR | V3: NR | W3: =IF(AND(ISNUMBER(U3),ISNUMBER(V3)),ROUND((U3+V3)/2,0),IF(ISNUMBER(U3),U3,IF(ISNUMBER(V3),V3,"NR"))) -> NR | X3: Not reported | Y3: 80-80 | Z3: no | AA3: 50+ sites / 700+ crashes | AB3: Before/after using empirical Bayes or full Bayes | AC3: The authors note that crash reduction effects decreased over time and speed, speed variability, and non-compliance to speed limits significantly increased over time. | AD3: Yes | AE3: Fatal & injury only | AF3: All crash types | AG3: Study sites were Principal Arterial Other Freeways and Expressways. Do NOT apply to collectors or local roads - the team ruled that out in review. AADT range not reported by the study - the selector cannot score AADT fit for this row. | AH3: No
A4: Implement Automated Speed Enforcement Cameras | B4: CM: Appropriate Speed Limits for All Road Users | C4: 0.46 | D4: 0.46 | E4: 0.46 | F4: 0.46 | G4: 0.46 | H4: 20 | L4: CMF: 2915 | M4: Original | N4: 4 | O4: Urban | P4: =C4 -> 0.46 | Q4: =IF(ISNUMBER(P4),ROUND((1-P4)*100,1),"NR") -> 54 | R4: All | S4: All | T4: Principal Arterial Other | U4: NR | V4: NR | W4: =IF(AND(ISNUMBER(U4),ISNUMBER(V4)),ROUND((U4+V4)/2,0),IF(ISNUMBER(U4),U4,IF(ISNUMBER(V4),V4,"NR"))) -> NR | X4: Not reported | Y4: NR | Z4: no | AA4: 25-49 sites / unknown crashes | AB4: Before/after using empirical Bayes or full Bayes | AC4: CMF is for "target" crashes. Target crashes are defined as those that occur during non-peak periods. Peak periods (6AM - 9 AM and 4PM - 7PM); Non-peak periods (remaining 18 hrs for weekdays, 24 hrs for weekends and holidays). | AD4: Yes | AE4: All crashes | AF4: All crash types | AG4: AADT range not reported by the study - the selector cannot score AADT fit for this row. | AH4: No
A5: Install Variable Speed Limit (Vsl) | B5: CM: Appropriate Speed Limits for All Road Users | C5: 0.66 | D5: 0.66 | E5: 0.66 | F5: 0.66 | G5: 0.66 | H5: 20 | L5: CMF: 11002 | M5: Original | N5: 3 | O5: Not specified | P5: =C5 -> 0.66 | Q5: =IF(ISNUMBER(P5),ROUND((1-P5)*100,1),"NR") -> 34 | R5: All | S5: All | T5: Principal Arterial Interstate | U5: 10194 | V5: 11090 | W5: =IF(AND(ISNUMBER(U5),ISNUMBER(V5)),ROUND((U5+V5)/2,0),IF(ISNUMBER(U5),U5,IF(ISNUMBER(V5),V5,"NR"))) -> 10642 | X5: Not reported | Y5: 35-75 | Z5: no | AA5: 50-99 sites / 700+ crashes | AB5: Regression cross-section | AD5: Yes | AE5: All crashes | AF5: All crash types | AG5: Study sites were Principal Arterial Interstate. Do NOT apply to collectors or local roads - the team ruled that out in review. Study AADT 10194-11090 is well below SCDOT's typical volume on that functional class (~17,000 average, higher on the busiest routes). Check the site AADT before using this CMF. Valid AADT range tested: 10,194-11,090. | AH5: No
A6: Install Variable Speed Limit | B6: CM: Appropriate Speed Limits for All Road Users | C6: 0.861 | D6: 0.861 | E6: 0.861 | F6: 0.861 | G6: 0.861 | H6: 20 | L6: CMF: 11832 | M6: Added | N6: 4 | O6: Not reported | P6: =C6 -> 0.861 | Q6: =IF(ISNUMBER(P6),ROUND((1-P6)*100,1),"NR") -> 13.9 | R6: K (fatal), A (serious injury), B (minor injury), C (possible injury) | S6: All | T6: Principal Arterial Interstate | U6: 53729 | V6: 282619 | W6: =IF(AND(ISNUMBER(U6),ISNUMBER(V6)),ROUND((U6+V6)/2,0),IF(ISNUMBER(U6),U6,IF(ISNUMBER(V6),V6,"NR"))) -> 168174 | X6: Not reported | Y6: NR | Z6: no | AA6: 50+ sites / unknown crashes | AB6: Before/after using empirical Bayes or full Bayes | AC6: This CMF is for I-5. | AD6: Yes | AE6: Fatal & injury only | AF6: All crash types | AG6: Study sites were Principal Arterial Interstate. Do NOT apply to collectors or local roads - the team ruled that out in review. Valid AADT range tested: 53,729-282,619. | AH6: No
A7: Install Dynamic Speed Feedback Sign | B7: CM: Appropriate Speed Limits for All Road Users | C7: 0.93 | D7: 0.93 | E7: 0.93 | F7: 0.93 | G7: 0.93 | H7: 20 | L7: CMF: 6886 | M7: Added | N7: 4 | O7: Rural | P7: =C7 -> 0.93 | Q7: =IF(ISNUMBER(P7),ROUND((1-P7)*100,1),"NR") -> 7 | R7: All | S7: All | T7: Not specified | U7: 400 | V7: 8400 | W7: =IF(AND(ISNUMBER(U7),ISNUMBER(V7)),ROUND((U7+V7)/2,0),IF(ISNUMBER(U7),U7,IF(ISNUMBER(V7),V7,"NR"))) -> 4400 | X7: Not reported | Y7: 50-65 | Z7: no | AA7: <25 or unknown sites / <250 crashes | AB7: Before/after using empirical Bayes or full Bayes | AC7: This CMF applies to two-lane rural horizontal curves for crashes involving vehicles traveling in the direction of the DSFS system. | AD7: Yes | AE7: All crashes | AF7: All crash types | AG7: Valid AADT range tested: 400-8,400. | AH7: No
A8: Install Automated Section Speed Enforcement System | B8: CM: Appropriate Speed Limits for All Road Users | C8: 0.563 | D8: 0.563 | E8: 0.563 | F8: 0.563 | G8: 0.563 | H8: 20 | L8: CMF: 7714 | M8: Added | N8: 5 | O8: Urban | P8: =C8 -> 0.563 | Q8: =IF(ISNUMBER(P8),ROUND((1-P8)*100,1),"NR") -> 43.7 | R8: All | S8: Single vehicle | T8: Principal Arterial Other Freeways and Expressways | U8: NR | V8: NR | W8: =IF(AND(ISNUMBER(U8),ISNUMBER(V8)),ROUND((U8+V8)/2,0),IF(ISNUMBER(U8),U8,IF(ISNUMBER(V8),V8,"NR"))) -> NR | X8: Not reported | Y8: 80-80 | Z8: no | AA8: 50+ sites / 700+ crashes | AB8: Before/after using empirical Bayes or full Bayes | AC8: The authors note that crash reduction effects decreased over time and speed, speed variability, and non-compliance to speed limits significantly increased over time. | AD8: Yes | AE8: All crashes | AF8: Only: Single vehicle | AG8: Study sites were Principal Arterial Other Freeways and Expressways. Do NOT apply to collectors or local roads - the team ruled that out in review. AADT range not reported by the study - the selector cannot score AADT fit for this row. | AH8: Yes
A9: Implement Mobile Automated Speed Enforcement System | B9: CM: Appropriate Speed Limits for All Road Users | C9: 0.799 | D9: 0.799 | E9: 0.799 | F9: 0.799 | G9: 0.799 | H9: 20 | L9: CMF: 7582 | M9: Added | N9: 5 | O9: Urban | P9: =C9 -> 0.799 | Q9: =IF(ISNUMBER(P9),ROUND((1-P9)*100,1),"NR") -> 20.1 | R9: K (fatal),A (serious injury),B (minor injury),C (possible injury) | S9: All | T9: Principal Arterial Other | U9: 2079 | V9: 22960 | W9: =IF(AND(ISNUMBER(U9),ISNUMBER(V9)),ROUND((U9+V9)/2,0),IF(ISNUMBER(U9),U9,IF(ISNUMBER(V9),V9,"NR"))) -> 12520 | X9: Not reported | Y9: NR | Z9: no | AA9: 50+ sites / 700+ crashes | AB9: Before/after using empirical Bayes or full Bayes | AC9: The number of crashes in the after period were not reported in this study | AD9: Yes | AE9: Fatal & injury only | AF9: All crash types | AG9: Valid AADT range tested: 2,079-22,960. | AH9: No
A10: Implement Automated Speed Enforcement Cameras | B10: CM: Appropriate Speed Limits for All Road Users | C10: 0.33 | D10: 0.33 | E10: 0.33 | F10: 0.33 | G10: 0.33 | H10: 20 | L10: CMF: 2923 | M10: Added | N10: 4 | O10: Urban | P10: =C10 -> 0.33 | Q10: =IF(ISNUMBER(P10),ROUND((1-P10)*100,1),"NR") -> 67 | R10: O (property damage only) | S10: Single vehicle | T10: Principal Arterial Other | U10: NR | V10: NR | W10: =IF(AND(ISNUMBER(U10),ISNUMBER(V10)),ROUND((U10+V10)/2,0),IF(ISNUMBER(U10),U10,IF(ISNUMBER(V10),V10,"NR"))) -> NR | X10: Not reported | Y10: NR | Z10: no | AA10: 25-49 sites / unknown crashes | AB10: Before/after using empirical Bayes or full Bayes | AC10: CMF is for "target" crashes. Target crashes are defined as those that occur during non-peak periods. Peak periods (6AM - 9 AM and 4PM - 7PM); Non-peak periods (remaining 18 hrs for weekdays, 24 hrs for weekends and holidays). | AD10: Yes | AE10: PDO only | AF10: Only: Single vehicle | AG10: AADT range not reported by the study - the selector cannot score AADT fit for this row. | AH10: Yes
A11: Install Automated Section Speed Enforcement System On Curves | B11: CM: Appropriate Speed Limits for All Road Users | C11: 0.57 | D11: 0.57 | E11: 0.57 | F11: 0.57 | G11: 0.57 | H11: 20 | L11: CMF: 4146 | M11: Added | N11: 4 | O11: Not specified | P11: =C11 -> 0.57 | Q11: =IF(ISNUMBER(P11),ROUND((1-P11)*100,1),"NR") -> 43 | R11: All | S11: All | T11: Principal Arterial Other Freeways and Expressways | U11: 23000 | V11: 42000 | W11: =IF(AND(ISNUMBER(U11),ISNUMBER(V11)),ROUND((U11+V11)/2,0),IF(ISNUMBER(U11),U11,IF(ISNUMBER(V11),V11,"NR"))) -> 32500 | X11: Not reported | Y11: 130-130 | Z11: no | AA11: 50+ sites / <250 crashes | AB11: Before/after using empirical Bayes or full Bayes | AD11: Yes | AE11: All crashes | AF11: All crash types | AG11: Study sites were Principal Arterial Other Freeways and Expressways. Do NOT apply to collectors or local roads - the team ruled that out in review. Valid AADT range tested: 23,000-42,000. | AH11: No
A12: Convert Traditional Or Flush Buffered Bike Lane To Sbl With Flexi-Posts | B12: CM: Bicycle Lanes | C12: 0.468 | D12: 0.468 | E12: 0.468 | F12: 0.468 | G12: 0.468 | H12: 20 | L12: CMF: 11296 | M12: Original | N12: 4 | O12: Urban | P12: =C12 -> 0.468 | Q12: =IF(ISNUMBER(P12),ROUND((1-P12)*100,1),"NR") -> 53.2 | R12: All | S12: Vehicle/bicycle | T12: Not specified | U12: NR | V12: NR | W12: =IF(AND(ISNUMBER(U12),ISNUMBER(V12)),ROUND((U12+V12)/2,0),IF(ISNUMBER(U12),U12,IF(ISNUMBER(V12),V12,"NR"))) -> NR | X12: Not reported | Y12: NR | Z12: no | AA12: 100+ sites / unknown crashes | AB12: Regression cross-section | AC12: The after condition is SBL with Flexible Delineator Posts. | AD12: Yes | AE12: All crashes | AF12: Only: Vehicle/bicycle | AG12: AADT range not reported by the study - the selector cannot score AADT fit for this row. | AH12: No
A13: Install Bicycle Lanes | B13: CM: Bicycle Lanes | C13: 0.51 | D13: 0.51 | E13: 0.51 | F13: 0.51 | G13: 0.51 | H13: 20 | L13: CMF: 10738 | M13: Original | N13: 4 | O13: Urban | P13: =C13 -> 0.51 | Q13: =IF(ISNUMBER(P13),ROUND((1-P13)*100,1),"NR") -> 49 | R13: All | S13: All | T13: All | U13: 10 | V13: 92462 | W13: =IF(AND(ISNUMBER(U13),ISNUMBER(V13)),ROUND((U13+V13)/2,0),IF(ISNUMBER(U13),U13,IF(ISNUMBER(V13),V13,"NR"))) -> 46236 | X13: Not reported | Y13: NR | Z13: no | AA13: 100+ sites / 700+ crashes | AB13: Regression cross-section | AC13: This CMF is for bicycle lane addition resulting in reduced shoulder or lane width and 20 percent increase in average daily bicycle traffic (ADBT). The base condition was 11-ft lanes, no shoulder, no median, and four-lane urban collector or local road. | AD13: Yes | AE13: All crashes | AF13: All crash types | AG13: Valid AADT range tested: 10-92,462. | AH13: No
A14: Install Bicycle Boulevard | B14: CM: Bicycle Lanes | C14: 0.37 | D14: 0.37 | E14: 0.37 | F14: 0.37 | G14: 0.37 | H14: 20 | L14: CMF: 3092 | M14: Added | N14: 4 | O14: Urban and suburban | P14: =C14 -> 0.37 | Q14: =IF(ISNUMBER(P14),ROUND((1-P14)*100,1),"NR") -> 63 | R14: All | S14: Vehicle/bicycle | T14: Not Specified | U14: NR | V14: NR | W14: =IF(AND(ISNUMBER(U14),ISNUMBER(V14)),ROUND((U14+V14)/2,0),IF(ISNUMBER(U14),U14,IF(ISNUMBER(V14),V14,"NR"))) -> NR | X14: Not reported | Y14: NR | Z14: no | AA14: 100+ sites / 700+ crashes | AB14: Non-regression cross-section | AD14: Yes | AE14: All crashes | AF14: Only: Vehicle/bicycle | AG14: AADT range not reported by the study | AH14: No
A15: Convert Flush Buffered Bike Lane To SBL With Flexi-Posts | B15: CM: Bicycle Lanes | C15: 0.441 | D15: 0.441 | E15: 0.441 | F15: 0.441 | G15: 0.441 | H15: 20 | L15: CMF: 11295 | M15: Added | N15: 4 | O15: Urban | P15: =C15 -> 0.441 | Q15: =IF(ISNUMBER(P15),ROUND((1-P15)*100,1),"NR") -> 55.9 | R15: All | S15: Vehicle/bicycle | T15: Not specified | U15: NR | V15: NR | W15: =IF(AND(ISNUMBER(U15),ISNUMBER(V15)),ROUND((U15+V15)/2,0),IF(ISNUMBER(U15),U15,IF(ISNUMBER(V15),V15,"NR"))) -> NR | X15: Not reported | Y15: NR | Z15: no | AA15: 100+ sites / unknown crashes | AB15: Regression cross-section | AC15: The after condition is SBL with Flexible Delineator Posts. | AD15: Yes | AE15: All crashes | AF15: Only: Vehicle/bicycle | AG15: AADT range not reported by the study - the selector cannot score AADT fit for this row. | AH15: No
A16: Install Separated Bicycle Lane | B16: CM: Bicycle Lanes | C16: 0.456 | D16: 0.456 | E16: 0.456 | F16: 0.456 | G16: 0.456 | H16: 20 | L16: CMF: 11553 | M16: Added | N16: 4 | O16: All | P16: =C16 -> 0.456 | Q16: =IF(ISNUMBER(P16),ROUND((1-P16)*100,1),"NR") -> 54.4 | R16: All | S16: All | T16: Not specified | U16: 2678 | V16: 46640 | W16: =IF(AND(ISNUMBER(U16),ISNUMBER(V16)),ROUND((U16+V16)/2,0),IF(ISNUMBER(U16),U16,IF(ISNUMBER(V16),V16,"NR"))) -> 24659 | X16: Roadway/roadway (not interchange related) | Y16: NR | Z16: no | AA16: 100+ sites / unknown crashes | AB16: Regression cross-section | AC16: This CMF is for non-weather related crashes. CMF is presented in Table 20 in the report | AD16: Yes | AE16: All crashes | AF16: All crash types | AG16: Valid AADT range tested: 2,678-46,640. | AH16: No
A17: Convert Traditional Bike Lane To SBL With Flexi-Posts | B17: CM: Bicycle Lanes | C17: 0.498 | D17: 0.498 | E17: 0.498 | F17: 0.498 | G17: 0.498 | H17: 20 | L17: CMF: 11294 | M17: Added | N17: 4 | O17: Urban | P17: =C17 -> 0.498 | Q17: =IF(ISNUMBER(P17),ROUND((1-P17)*100,1),"NR") -> 50.2 | R17: All | S17: Vehicle/bicycle | T17: Not specified | U17: NR | V17: NR | W17: =IF(AND(ISNUMBER(U17),ISNUMBER(V17)),ROUND((U17+V17)/2,0),IF(ISNUMBER(U17),U17,IF(ISNUMBER(V17),V17,"NR"))) -> NR | X17: Not reported | Y17: NR | Z17: no | AA17: 100+ sites / unknown crashes | AB17: Regression cross-section | AC17: The after condition is SBL with Flexible Delineator Posts. | AD17: Yes | AE17: All crashes | AF17: Only: Vehicle/bicycle | AG17: AADT range not reported by the study - the selector cannot score AADT fit for this row. | AH17: No
A18: Convert Flush Buffered Bike Lane To SBL With A Blend Of Flexi-Post And Other Vertical Elements | B18: CM: Bicycle Lanes | C18: 0.567 | D18: 0.567 | E18: 0.567 | F18: 0.567 | G18: 0.567 | H18: 20 | L18: CMF: 11302 | M18: Added | N18: 4 | O18: Urban | P18: =C18 -> 0.567 | Q18: =IF(ISNUMBER(P18),ROUND((1-P18)*100,1),"NR") -> 43.3 | R18: All | S18: Vehicle/bicycle | T18: Not specified | U18: NR | V18: NR | W18: =IF(AND(ISNUMBER(U18),ISNUMBER(V18)),ROUND((U18+V18)/2,0),IF(ISNUMBER(U18),U18,IF(ISNUMBER(V18),V18,"NR"))) -> NR | X18: Not reported | Y18: NR | Z18: no | AA18: 100+ sites / unknown crashes | AB18: Regression cross-section | AC18: The after condition is SBL with blend of flexible delineator posts and other vertical elements. | AD18: Yes | AE18: All crashes | AF18: Only: Vehicle/bicycle | AG18: AADT range not reported by the study - the selector cannot score AADT fit for this row. | AH18: No
A19: Install Bicycle Lanes | B19: CM: Bicycle Lanes | C19: 0.571 | D19: 0.571 | E19: 0.571 | F19: 0.571 | G19: 0.571 | H19: 20 | L19: CMF: 11555 | M19: Added | N19: 4 | O19: All | P19: =C19 -> 0.571 | Q19: =IF(ISNUMBER(P19),ROUND((1-P19)*100,1),"NR") -> 42.9 | R19: K (fatal), A (serious injury), B (minor injury), C (possible injury) | S19: All | T19: Not specified | U19: 2678 | V19: 46640 | W19: =IF(AND(ISNUMBER(U19),ISNUMBER(V19)),ROUND((U19+V19)/2,0),IF(ISNUMBER(U19),U19,IF(ISNUMBER(V19),V19,"NR"))) -> 24659 | X19: Roadway/roadway (not interchange related) | Y19: NR | Z19: no | AA19: 100+ sites / unknown crashes | AB19: Regression cross-section | AC19: This CMF is for intersections with bike lanes mixed with through and right turn lanes. CMF is presented in Table 18 in the report. | AD19: Yes | AE19: Fatal & injury only | AF19: All crash types | AG19: Valid AADT range tested: 2,678-46,640. | AH19: No
A20: Install High-Visibility Crosswalk | B20: CM: Crosswalk Visibility Enhancements | C20: 0.6 | D20: 0.6 | E20: 0.6 | F20: 0.6 | G20: 0.6 | H20: 20 | L20: CMF: 4123 | M20: Original | N20: 2 | O20: Urban | P20: =C20 -> 0.6 | Q20: =IF(ISNUMBER(P20),ROUND((1-P20)*100,1),"NR") -> 40 | R20: All | S20: Vehicle/pedestrian | T20: Not Specified | U20: NR | V20: NR | W20: =IF(AND(ISNUMBER(U20),ISNUMBER(V20)),ROUND((U20+V20)/2,0),IF(ISNUMBER(U20),U20,IF(ISNUMBER(V20),V20,"NR"))) -> NR | X20: Roadway/roadway (not interchange related) | Y20: NR | Z20: no | AA20: 50+ sites / 500-699 crashes | AB20: Simple before/after | AC20: The treatment group included both signalized and unsignalized intersections. The corresponding change in crashes in the comparison group was an 18 percent reduction in pedestrian-vehicle crashes. | AD20: Yes | AE20: All crashes | AF20: Only: Vehicle/pedestrian | AG20: AADT range not reported by the study - the selector cannot score AADT fit for this row. | AH20: No
A21: Provide Intersection Illumination | B21: CM: Crosswalk Visibility Enhancements | C21: 0.58 | D21: 0.58 | E21: 0.58 | F21: 0.58 | G21: 0.58 | H21: 20 | L21: CMF: 436 | M21: Original | N21: 3 | O21: Not Specified | P21: =C21 -> 0.58 | Q21: =IF(ISNUMBER(P21),ROUND((1-P21)*100,1),"NR") -> 42 | R21: A (serious injury),B (minor injury),C (possible injury) | S21: Nighttime,Vehicle/pedestrian | T21: Not Specified | U21: NR | V21: NR | W21: =IF(AND(ISNUMBER(U21),ISNUMBER(V21)),ROUND((U21+V21)/2,0),IF(ISNUMBER(U21),U21,IF(ISNUMBER(V21),V21,"NR"))) -> NR | X21: Roadway/roadway (not interchange related) | Y21: NR | Z21: italics | AA21: <25 or unknown sites / <250 crashes | AB21: Meta-analysis | AC21: Countermeasure name changed to match HSM | AD21: Yes | AE21: Fatal & injury only | AF21: Only: Nighttime,Vehicle/pedestrian | AG21: AADT range not reported by the study - the selector cannot score AADT fit for this row. | AH21: No
A22: Install High-Visibility Yellow, Continental Type Crosswalks At Schools | B22: CM: Crosswalk Visibility Enhancements | C22: 0.63 | D22: 0.63 | E22: 0.63 | F22: 0.63 | G22: 0.63 | H22: 20 | L22: CMF: 2697 | M22: Added | N22: 4 | O22: Urban | P22: =C22 -> 0.63 | Q22: =IF(ISNUMBER(P22),ROUND((1-P22)*100,1),"NR") -> 37 | R22: All | S22: Vehicle/pedestrian | T22: Not Specified | U22: 567 | V22: 43199 | W22: =IF(AND(ISNUMBER(U22),ISNUMBER(V22)),ROUND((U22+V22)/2,0),IF(ISNUMBER(U22),U22,IF(ISNUMBER(V22),V22,"NR"))) -> 21883 | X22: Not reported | Y22: NR | Z22: no | AA22: 50+ sites / 250-499 crashes | AB22: Before/after using empirical Bayes or full Bayes | AD22: Yes | AE22: All crashes | AF22: Only: Vehicle/pedestrian | AG22: Valid AADT range tested: 567-43,199. | AH22: No
A23: Modify Signal Phasing (Implement A Leading Pedestrian Interval) | B23: CM: Leading Pedestrian Interval | C23: 0.87 | D23: 0.87 | E23: 0.87 | F23: 0.87 | G23: 0.87 | H23: 20 | L23: CMF: 9918 | M23: Original | N23: 5 | O23: Urban and suburban | P23: =C23 -> 0.87 | Q23: =IF(ISNUMBER(P23),ROUND((1-P23)*100,1),"NR") -> 13 | R23: All | S23: Vehicle/pedestrian | T23: All | U23: NR | V23: NR | W23: =IF(AND(ISNUMBER(U23),ISNUMBER(V23)),ROUND((U23+V23)/2,0),IF(ISNUMBER(U23),U23,IF(ISNUMBER(V23),V23,"NR"))) -> NR | X23: Roadway/roadway (not interchange related) | Y23: NR | Z23: no | AA23: 50+ sites / 700+ crashes | AB23: Before/after using empirical Bayes or full Bayes | AC23: Crash Type = Vehicle - Pedestrian Crashes. This CMF is for sites where LPIs were implemented either at all crossings (across major and minor roads) or only for crossings across the minor road (parallel to the major road). | AD23: Yes | AE23: All crashes | AF23: Only: Vehicle/pedestrian | AG23: AADT range not reported by the study - the selector cannot score AADT fit for this row. | AH23: No
A24: Modify Signal Phasing (Implement A Leading Pedestrian Interval) | B24: CM: Leading Pedestrian Interval | C24: 0.81 | D24: 0.81 | E24: 0.81 | F24: 0.81 | G24: 0.81 | H24: 20 | L24: CMF: 9903 | M24: Added | N24: 5 | O24: Urban and suburban | P24: =C24 -> 0.81 | Q24: =IF(ISNUMBER(P24),ROUND((1-P24)*100,1),"NR") -> 19 | R24: All | S24: Vehicle/pedestrian | T24: All | U24: 6650 | V24: 32363 | W24: =IF(AND(ISNUMBER(U24),ISNUMBER(V24)),ROUND((U24+V24)/2,0),IF(ISNUMBER(U24),U24,IF(ISNUMBER(V24),V24,"NR"))) -> 19507 | X24: Roadway/roadway (not interchange related) | Y24: NR | Z24: no | AA24: 50+ sites / 700+ crashes | AB24: Before/after using empirical Bayes or full Bayes | AC24: Crash Type = Vehicle - Pedestrian Crashes. This CMF is for sites where LPIs were implemented either at all crossings (across major and minor roads) or only for crossings across the minor road (parallel to the major road). | AD24: Yes | AE24: All crashes | AF24: Only: Vehicle/pedestrian | AG24: Valid AADT range tested: 6,650-32,363. | AH24: No
A25: Install Raised Median With Marked Crosswalk (Uncontrolled) | B25: CM: Medians and Pedestrian Refuge Islands in Urban and Suburban Areas | C25: 0.54 | D25: 0.54 | E25: 0.54 | F25: 0.54 | G25: 0.54 | H25: 20 | L25: CMF: 175 | M25: Original | N25: 3 | O25: Urban and Suburban | P25: =C25 -> 0.54 | Q25: =IF(ISNUMBER(P25),ROUND((1-P25)*100,1),"NR") -> 46 | R25: All | S25: Vehicle/pedestrian | T25: Principal Arterial Other | U25: 15000 | V25: NR | W25: =IF(AND(ISNUMBER(U25),ISNUMBER(V25)),ROUND((U25+V25)/2,0),IF(ISNUMBER(U25),U25,IF(ISNUMBER(V25),V25,"NR"))) -> 15000 | X25: Not reported | Y25: NR | Z25: no | AA25: 100+ sites / <250 crashes | AB25: Non-regression cross-section | AC25: The study design was a simple comparison of crash rates, controlling for pedestrian and traffic volume. | AD25: Yes | AE25: All crashes | AF25: Only: Vehicle/pedestrian | AH25: No
A26: Install Raised Median With Or Without Marked Crosswalk (Uncontrolled) | B26: CM: Medians and Pedestrian Refuge Islands in Urban and Suburban Areas | C26: 0.685 | D26: 0.685 | E26: 0.685 | F26: 0.685 | G26: 0.685 | H26: 20 | L26: CMF: 8799 | M26: Added | N26: 4 | O26: Urban and suburban | P26: =C26 -> 0.685 | Q26: =IF(ISNUMBER(P26),ROUND((1-P26)*100,1),"NR") -> 31.5 | R26: All | S26: Vehicle/pedestrian | T26: Minor Arterial | U26: 1245 | V26: 46000 | W26: =IF(AND(ISNUMBER(U26),ISNUMBER(V26)),ROUND((U26+V26)/2,0),IF(ISNUMBER(U26),U26,IF(ISNUMBER(V26),V26,"NR"))) -> 23623 | X26: Not reported | Y26: NR | Z26: no | AA26: 100+ sites / 700+ crashes | AB26: Meta-analysis | AC26: Combination of EB before-after and cross-sectional estimations. | AD26: Yes | AE26: All crashes | AF26: Only: Vehicle/pedestrian | AG26: Valid AADT range tested: 1,245-46,000. | AH26: No
A27: Install Raised Median | B27: CM: Medians and Pedestrian Refuge Islands in Urban and Suburban Areas | C27: 0.29 | D27: 0.29 | E27: 0.29 | F27: 0.29 | G27: 0.29 | H27: 20 | L27: CMF: 2219 | M27: Added | N27: 4 | O27: Urban | P27: =C27 -> 0.29 | Q27: =IF(ISNUMBER(P27),ROUND((1-P27)*100,1),"NR") -> 71 | R27: All | S27: All | T27: Principal Arterial Other | U27: 1390 | V27: 51200 | W27: =IF(AND(ISNUMBER(U27),ISNUMBER(V27)),ROUND((U27+V27)/2,0),IF(ISNUMBER(U27),U27,IF(ISNUMBER(V27),V27,"NR"))) -> 26295 | X27: Not reported | Y27: NR | Z27: no | AA27: 100+ sites / 700+ crashes | AB27: Regression cross-section | AD27: Yes | AE27: All crashes | AF27: All crash types | AG27: Valid AADT range tested: 1,390-51,200. | AH27: No
